Workbook

Sheet gestion Stan  Dams
B5: Règle de sélection des favoris pour les phases finales ? | E5: Quels points ?
B11: Attention ne surtout pas toucher !!!!! Save des formules
B13: Fomule prono : | C13: =IF(J6=F6,IF( OR(I6="3 - 1",I6="4 - 1",I6="4 - 2"),100,IF( OR(I6="2 - 1",I6="3 - 2",I6="4 - 3"),75,IF( OR(I6="3 - 4",I6="2 - 3",I6="1 - 2"),50,IF( OR(I6="1 - 3",I6="2 - 4"),25,0))))) -> 0 | E13: Fomule qualif : | G13: =IF(J6=F6,IF( OR(I6="3 - 1",I6="4 - 1",I6="4 - 2"),100,IF( OR(I6="2 - 1",I6="3 - 2",I6="4 - 3"),75,IF( OR(I6="3 - 4",I6="2 - 3",I6="1 - 2"),50,IF( OR(I6="1 - 3",I6="2 - 4"),25,0)))))+IF(K6=G6,+75,0)+IF(L6="oui",+50,0) -> 75
E15: Fomule 8e finale : | G15: =IF(K4="oui",50,0)+IF(I4=E4,IF(H4="R",75,IF(H4="S",25,0))+IF(J4=F4,+75,0),0) -> 75
E17: Formule Nbr score exact : | G17: =SUMPRODUCT(('Dams 1'!G7:G12='Dams 1'!K7:K12)*1)+SUMPRODUCT(('Dams 1'!G16:G21='Dams 1'!K16:K21)*1)+SUMPRODUCT(('Dams 1'!G25:G30='Dams 1'!K25:K30)*1)+SUMPRODUCT(('Dams 1'!G34:G39='Dams 1'!K34:K39)*1)+SUMPRODUCT(('Dams 1'!G43:G48='Dams 1'!K43:K48)*1)+SUMPRODUCT(('Dams 1'!G52:G57='Dams 1'!K52:K57)*1)+SUMPRODUCT(('Dams 1'!G61:G66='Dams 1'!K61:K66)*1)+SUMPRODUCT(('Dams 1'!G70:G75='Dams 1'!K70:K75)*1)+SUMPRODUCT(('Dams 1'!G79:G84='Dams 1'!K79:K84)*1)+SUMPRODUCT(('Dams 1'!G88:G93='Dams 1'!K88:K93)*1)+SUMPRODUCT(('Dams 1'!G97:G102='Dams 1'!K97:K102)*1)+SUMPRODUCT(('Dams 1'!G106:G111='Dams 1'!K106:K111)*1) -> 0
E19: Formule Nbr pronoo exact : | G19: =SUMPRODUCT(('Dams 1'!F7:F12='Dams 1'!J7:J12)*1)+SUMPRODUCT(('Dams 1'!F16:F21='Dams 1'!J16:J21)*1)+SUMPRODUCT(('Dams 1'!F25:F30='Dams 1'!J25:J30)*1)+SUMPRODUCT(('Dams 1'!F34:F39='Dams 1'!J34:J39)*1)+SUMPRODUCT(('Dams 1'!F43:F48='Dams 1'!J43:J48)*1)+SUMPRODUCT(('Dams 1'!F52:F57='Dams 1'!J52:J57)*1)+SUMPRODUCT(('Dams 1'!F61:F66='Dams 1'!J61:J66)*1)+SUMPRODUCT(('Dams 1'!F70:F75='Dams 1'!J70:J75)*1)+SUMPRODUCT(('Dams 1'!F79:F84='Dams 1'!J79:J84)*1)+SUMPRODUCT(('Dams 1'!F88:F93='Dams 1'!J88:J93)*1)+SUMPRODUCT(('Dams 1'!F97:F102='Dams 1'!J97:J102)*1)+SUMPRODUCT(('Dams 1'!F106:F111='Dams 1'!J106:J111)*1) -> 2
D23: Rang | E23: A | F23: =SUM(F24:F27) -> 141 | G23: Rang | H23: B | I23: =SUM(I24:I27) -> 169 | J23: Rang | K23: C | L23: =SUM(L24:L27) -> 140 | M23: Rang | N23: D | O23: =SUM(O24:O27) -> 105
D24: 1 | E24: Mexique | F24: 15 | G24: 2 | H24: Canada | I24: 30 | J24: 1 | K24: Bresil | L24: 6 | M24: 1 | N24: Etat Unis | O24: 16
A25: Equipes | B25: 1 | C25: I | D25: 2 | E25: Coree du sud | F25: 25 | G25: 1 | H25: Suisse | I25: 19 | J25: 2 | K25: Maroc | L25: 8 | M25: 3 | N25: Australie | O25: 27
B26: 2 | C26: D | D26: 4 | E26: Afrique du sud | F26: 60 | G26: 3 | H26: Qatar | I26: 55 | J26: 3 | K26: Ecosse | L26: 43 | M26: 4 | N26: Paraguay | O26: 40
B27: 3 | C27: F | D27: 3 | E27: Republique Tcheque | F27: 41 | G27: 4 | H27: Bosnie | I27: 65 | J27: 4 | K27: Haïti | L27: 83 | M27: 2 | N27: Turquie | O27: 22
B28: 4 | C28: K
B29: 5 | C29: J | D29: Rang | E29: E | F29: =SUM(F30:F33) -> 149 | G29: Rang | H29: F | I29: =SUM(I30:I33) -> 107 | J29: Rang | K29: G | L29: =SUM(L30:L33) -> 144 | M29: Rang | N29: H | O29: =SUM(O30:O33) -> 149
B30: 6 | C30: L | D30: 1 | E30: Allemagne | F30: 10 | G30: 1 | H30: Pays Bas | I30: 7 | J30: 1 | K30: Belgique | L30: 9 | M30: 1 | N30: Espagne | O30: 2
B31: 7 | C31: C | D31: 2 | E31: Equateur | F31: 23 | G31: 2 | H31: Japon | I31: 18 | J31: 2 | K31: Iran | L31: 21 | M31: 2 | N31: Uruguay | O31: 17
B32: 8 | C32: A | D32: 3 | E32: Cote d'Ivoire | F32: 34 | G32: 4 | H32: Tunisie | I32: 44 | J32: 3 | K32: Egypte | L32: 29 | M32: 3 | N32: Arabie Saoudite | O32: 61
B33: 9 | C33: G | D33: 4 | E33: Curaçao | F33: 82 | G33: 3 | H33: Suede | I33: 38 | J33: 4 | K33: Nouvelle Zelande | L33: 85 | M33: 4 | N33: Cap Vert | O33: 69
B34: 10 | C34: E
B35: 11 | C35: H | D35: Rang | E35: I | F35: =SUM(F36:F39) -> 103 | G35: Rang | H35: J | I35: =SUM(I36:I39) -> 118 | J35: Rang | K35: K | L35: =SUM(L36:L39) -> 114 | M35: Rang | N35: L | O35: =SUM(O36:O39) -> 122
B36: 12 | C36: B | D36: 1 | E36: France | F36: 1 | G36: 1 | H36: Argentine | I36: 3 | J36: 1 | K36: Portugal | L36: 5 | M36: 1 | N36: Angleterre | O36: 4
D37: 2 | E37: Senegal | F37: 14 | G37: 2 | H37: Autriche | I37: 24 | J37: 2 | K37: Colombie | L37: 13 | M37: 2 | N37: Croacie | O37: 11
D38: 3 | E38: Norvege | F38: 31 | G38: 3 | H38: Algerie | I38: 28 | J38: 4 | K38: Ouzbekistan | L38: 50 | M38: 3 | N38: Panama | O38: 33
D39: 4 | E39: Irak | F39: 57 | G39: 4 | H39: Jordanie | I39: 63 | J39: 3 | K39: RD Congo | L39: 46 | M39: 4 | N39: Ghana | O39: 74

Sheet Présentation 
C2: Grand Tournois Coupe du monde 2026 du Rattepit Fc
A5: Joueurs : | D5: Un objectif : | E5: Le poduim se fait offrir le restau par les 3 moins bien classés
A6: Dam's | B6: Stan
A7: Léna | B7: Pata | D7: Organisation : | E7: Début des hostilités le 11 Juin 2026
A8: Goyt | B8: Marina | E8: 104 matchs à pronostiquer des phases de poule à la finale
A9: Noé | B9: Ricco
A10: Clara | B10: Vero
A11: Erwan | B11: Hugo C. | D11: Les règles : | E11: Assumes tous tes pronos et flex quand tu encaisses les points avec un bon choix de booster !
A12: Jess | B12: Jeje | E12: TrashTalk autorisé et encouragé en toutes circonstances
A13: Micka | B13: Laura | E13: Un seul booster par jour maximum !
A14: Greg | B14: Paco
A15: Shervan | B15: Cyrille | D15: Fonctionnement : | E15: Le calcule des points est déterminé en fonction des risques pris lors du prono. Plus un prono est jugé risqué plus il rapporte de points et inversement. Le risque des pronos est determiné par le classement FIFA des équipes en date du début de la compétiton au sein de leur poule. Ainsi, est attribué à chaque équipe une valeur de 1 à 4 (1 étant le top et 4 étant le flop).
A16: Chloé | B16: Joris
A17: Steph | B17: Mathys
A18: Aymeric | B18: Kalash
A19: Nikola | B19: Hugo.O
E20: Vous disposez donc de 5 types de prono :
E21: Le prono SAFE (1-3 ; 1-4 ; 2-4) -> prono sur l'équipe ayant 2 rangs suppérieurs par rapport à son adversaire.
E22: Le prono M-S (1-2 ; 2-3 ; 3-4) -> prono sur l'équipe ayant 1 rang suppérieur par rapport à son adversaire.
E23: Le prono Nul -> prono sur le scénario où aucune des deux équipes ne prend le dessus sur l'autre.
E24: Le prono M-R (2-1 ; 3-2 ; 4-3) -> prono sur l'équipe ayant 1 rang inférieur par rapport à son adversaire.
E25: Le prono RISQUÉ (3-1 ; 4-1 ; 4-2) -> prono sur l'équipe ayant 2 rangs inférieurs par rapport à son adversaire.
D27: Les points : | E27: Prono SAFE : 25 pts | H27: Les Boosters : | I27: Booster validé = +50pts
E28: Prono M-S : 50 pts
E29: Prono Nul : 60 pts
E30: Prono M-R : 75 pts | H30: Score parfait : | I30: Tu trouves le score exact = jackpot +75pts
E31: Prono RISQUÉ : 100 pts
D33: Faire ses pronos : | E33: Dans vos onglets individuels vous n'avez qu'à remplir les colonnes "F" , "G" et "H".
E34: Faite bien attention à ne pas mettre d'espace en trop au moment de remplir pronos et scores.
E35: Les scores doivent être rédigé comme ci : "2 - 2" (score, espace, tiret, espace, score).
E36: Si vous souhaitez utiliser un bonus, vous devez écrire le numéro du booster "B1, ..." dans la ligne du match en colone "H".

Sheet Equipes
B2: Rang | C2: A | E2: Rang | F2: B | H2: Rang | I2: C | K2: Rang | L2: D
B3: 1 | C3: Mexique | E3: 2 | F3: Canada | H3: 1 | I3: Bresil | K3: 1 | L3: Etat Unis
B4: 2 | C4: Coree du sud | E4: 1 | F4: Suisse | H4: 2 | I4: Maroc | K4: 3 | L4: Australie
B5: 4 | C5: Afrique du sud | E5: 3 | F5: Qatar | H5: 3 | I5: Ecosse | K5: 4 | L5: Paraguay
B6: 3 | C6: Republique Tcheque | E6: 4 | F6: Bosnie | H6: 4 | I6: Haïti | K6: 2 | L6: Turquie
B8: Rang | C8: E | E8: Rang | F8: F | H8: Rang | I8: G | K8: Rang | L8: H
B9: 1 | C9: Allemagne | E9: 1 | F9: Pays Bas | H9: 1 | I9: Belgique | K9: 1 | L9: Espagne
B10: 2 | C10: Equateur | E10: 2 | F10: Japon | H10: 2 | I10: Iran | K10: 2 | L10: Uruguay
B11: 3 | C11: Cote d'Ivoire | E11: 4 | F11: Tunisie | H11: 3 | I11: Egypte | K11: 3 | L11: Arabie Saoudite
B12: 4 | C12: Curaçao | E12: 3 | F12: Suede | H12: 4 | I12: Nouvelle Zelande | K12: 4 | L12: Cap Vert
B14: Rang | C14: I | E14: Rang | F14: J | H14: Rang | I14: K | K14: Rang | L14: L
B15: 1 | C15: France | E15: 1 | F15: Argentine | H15: 1 | I15: Portugal | K15: 1 | L15: Angleterre
B16: 2 | C16: Senegal | E16: 2 | F16: Autriche | H16: 2 | I16: Colombie | K16: 2 | L16: Croacie
B17: 3 | C17: Norvege | E17: 3 | F17: Algerie | H17: 4 | I17: Ouzbekistan | K17: 3 | L17: Panama
B18: 4 | C18: Irak | E18: 4 | F18: Jordanie | H18: 3 | I18: RD Congo | K18: 4 | L18: Ghana

Sheet Classement
B2: Joueurs | C2: Nbr prono exact | D2: Nbr score exact | E2: Points | F2: Classement
B3: Dam's | C3: =SUMPRODUCT(('Dams 1'!F7:F12='Dams 1'!J7:J12)*1)+SUMPRODUCT(('Dams 1'!F16:F21='Dams 1'!J16:J21)*1)+SUMPRODUCT(('Dams 1'!F25:F30='Dams 1'!J25:J30)*1)+SUMPRODUCT(('Dams 1'!F34:F39='Dams 1'!J34:J39)*1)+SUMPRODUCT(('Dams 1'!F43:F48='Dams 1'!J43:J48)*1)+SUMPRODUCT(('Dams 1'!F52:F57='Dams 1'!J52:J57)*1)+SUMPRODUCT(('Dams 1'!F61:F66='Dams 1'!J61:J66)*1)+SUMPRODUCT(('Dams 1'!F70:F75='Dams 1'!J70:J75)*1)+SUMPRODUCT(('Dams 1'!F79:F84='Dams 1'!J79:J84)*1)+SUMPRODUCT(('Dams 1'!F88:F93='Dams 1'!J88:J93)*1)+SUMPRODUCT(('Dams 1'!F97:F102='Dams 1'!J97:J102)*1)+SUMPRODUCT(('Dams 1'!F106:F111='Dams 1'!J106:J111)*1) -> 2 | D3: =SUMPRODUCT(('Dams 1'!G7:G12='Dams 1'!K7:K12)*1)+SUMPRODUCT(('Dams 1'!G16:G21='Dams 1'!K16:K21)*1)+SUMPRODUCT(('Dams 1'!G25:G30='Dams 1'!K25:K30)*1)+SUMPRODUCT(('Dams 1'!G34:G39='Dams 1'!K34:K39)*1)+SUMPRODUCT(('Dams 1'!G43:G48='Dams 1'!K43:K48)*1)+SUMPRODUCT(('Dams 1'!G52:G57='Dams 1'!K52:K57)*1)+SUMPRODUCT(('Dams 1'!G61:G66='Dams 1'!K61:K66)*1)+SUMPRODUCT(('Dams 1'!G70:G75='Dams 1'!K70:K75)*1)+SUMPRODUCT(('Dams 1'!G79:G84='Dams 1'!K79:K84)*1)+SUMPRODUCT(('Dams 1'!G88:G93='Dams 1'!K88:K93)*1)+SUMPRODUCT(('Dams 1'!G97:G102='Dams 1'!K97:K102)*1)+SUMPRODUCT(('Dams 1'!G106:G111='Dams 1'!K106:K111)*1) -> 0 | E3: =SUM('Dams 1'!M:M)+SUM('Dams 2'!M:M) -> 50 | F3: =RANK(E3,E:E,0) -> 27
B4: Stan | C4: =SUMPRODUCT(('Stan 1'!F7:F12='Stan 1'!J7:J12)*1)+SUMPRODUCT(('Stan 1'!F16:F21='Stan 1'!J16:J21)*1)+SUMPRODUCT(('Stan 1'!F25:F30='Stan 1'!J25:J30)*1)+SUMPRODUCT(('Stan 1'!F34:F39='Stan 1'!J34:J39)*1)+SUMPRODUCT(('Stan 1'!F43:F48='Stan 1'!J43:J48)*1)+SUMPRODUCT(('Stan 1'!F52:F57='Stan 1'!J52:J57)*1)+SUMPRODUCT(('Stan 1'!F61:F66='Stan 1'!J61:J66)*1)+SUMPRODUCT(('Stan 1'!F70:F75='Stan 1'!J70:J75)*1)+SUMPRODUCT(('Stan 1'!F79:F84='Stan 1'!J79:J84)*1)+SUMPRODUCT(('Stan 1'!F88:F93='Stan 1'!J88:J93)*1)+SUMPRODUCT(('Stan 1'!F97:F102='Stan 1'!J97:J102)*1)+SUMPRODUCT(('Stan 1'!F106:F111='Stan 1'!J106:J111)*1) -> 2 | D4: =SUMPRODUCT(('Stan 1'!G7:G12='Stan 1'!K7:K12)*1)+SUMPRODUCT(('Stan 1'!G16:G21='Stan 1'!K16:K21)*1)+SUMPRODUCT(('Stan 1'!G25:G30='Stan 1'!K25:K30)*1)+SUMPRODUCT(('Stan 1'!G34:G39='Stan 1'!K34:K39)*1)+SUMPRODUCT(('Stan 1'!G43:G48='Stan 1'!K43:K48)*1)+SUMPRODUCT(('Stan 1'!G52:G57='Stan 1'!K52:K57)*1)+SUMPRODUCT(('Stan 1'!G61:G66='Stan 1'!K61:K66)*1)+SUMPRODUCT(('Stan 1'!G70:G75='Stan 1'!K70:K75)*1)+SUMPRODUCT(('Stan 1'!G79:G84='Stan 1'!K79:K84)*1)+SUMPRODUCT(('Stan 1'!G88:G93='Stan 1'!K88:K93)*1)+SUMPRODUCT(('Stan 1'!G97:G102='Stan 1'!K97:K102)*1)+SUMPRODUCT(('Stan 1'!G106:G111='Stan 1'!K106:K111)*1) -> 1 | E4: =SUM('Stan 1'!M:M)+Y72 -> 175 | F4: =RANK(E4,E:E,0) -> 8
B5: Pata | C5: =SUMPRODUCT(('Pata 1'!F7:F12='Pata 1'!J7:J12)*1)+SUMPRODUCT(('Pata 1'!F16:F21='Pata 1'!J16:J21)*1)+SUMPRODUCT(('Pata 1'!F25:F30='Pata 1'!J25:J30)*1)+SUMPRODUCT(('Pata 1'!F34:F39='Pata 1'!J34:J39)*1)+SUMPRODUCT(('Pata 1'!F43:F48='Pata 1'!J43:J48)*1)+SUMPRODUCT(('Pata 1'!F52:F57='Pata 1'!J52:J57)*1)+SUMPRODUCT(('Pata 1'!F61:F66='Pata 1'!J61:J66)*1)+SUMPRODUCT(('Pata 1'!F70:F75='Pata 1'!J70:J75)*1)+SUMPRODUCT(('Pata 1'!F79:F84='Pata 1'!J79:J84)*1)+SUMPRODUCT(('Pata 1'!F88:F93='Pata 1'!J88:J93)*1)+SUMPRODUCT(('Pata 1'!F97:F102='Pata 1'!J97:J102)*1)+SUMPRODUCT(('Pata 1'!F106:F111='Pata 1'!J106:J111)*1) -> 2 | D5: =SUMPRODUCT(('Pata 1'!G7:G12='Pata 1'!K7:K12)*1)+SUMPRODUCT(('Pata 1'!G16:G21='Pata 1'!K16:K21)*1)+SUMPRODUCT(('Pata 1'!G25:G30='Pata 1'!K25:K30)*1)+SUMPRODUCT(('Pata 1'!G34:G39='Pata 1'!K34:K39)*1)+SUMPRODUCT(('Pata 1'!G43:G48='Pata 1'!K43:K48)*1)+SUMPRODUCT(('Pata 1'!G52:G57='Pata 1'!K52:K57)*1)+SUMPRODUCT(('Pata 1'!G61:G66='Pata 1'!K61:K66)*1)+SUMPRODUCT(('Pata 1'!G70:G75='Pata 1'!K70:K75)*1)+SUMPRODUCT(('Pata 1'!G79:G84='Pata 1'!K79:K84)*1)+SUMPRODUCT(('Pata 1'!G88:G93='Pata 1'!K88:K93)*1)+SUMPRODUCT(('Pata 1'!G97:G102='Pata 1'!K97:K102)*1)+SUMPRODUCT(('Pata 1'!G106:G111='Pata 1'!K106:K111)*1) -> 0 | E5: =SUM('Pata 1'!M:M)+Y73 -> 100 | F5: =RANK(E5,E:E,0) -> 17
B6: Marina | C6: =SUMPRODUCT(('Marina 1'!F7:F12='Marina 1'!J7:J12)*1)+SUMPRODUCT(('Marina 1'!F16:F21='Marina 1'!J16:J21)*1)+SUMPRODUCT(('Marina 1'!F25:F30='Marina 1'!J25:J30)*1)+SUMPRODUCT(('Marina 1'!F34:F39='Marina 1'!J34:J39)*1)+SUMPRODUCT(('Marina 1'!F43:F48='Marina 1'!J43:J48)*1)+SUMPRODUCT(('Marina 1'!F52:F57='Marina 1'!J52:J57)*1)+SUMPRODUCT(('Marina 1'!F61:F66='Marina 1'!J61:J66)*1)+SUMPRODUCT(('Marina 1'!F70:F75='Marina 1'!J70:J75)*1)+SUMPRODUCT(('Marina 1'!F79:F84='Marina 1'!J79:J84)*1)+SUMPRODUCT(('Marina 1'!F88:F93='Marina 1'!J88:J93)*1)+SUMPRODUCT(('Marina 1'!F97:F102='Marina 1'!J97:J102)*1)+SUMPRODUCT(('Marina 1'!F106:F111='Marina 1'!J106:J111)*1) -> 2 | D6: =SUMPRODUCT(('Marina 1'!G7:G12='Marina 1'!K7:K12)*1)+SUMPRODUCT(('Marina 1'!G16:G21='Marina 1'!K16:K21)*1)+SUMPRODUCT(('Marina 1'!G25:G30='Marina 1'!K25:K30)*1)+SUMPRODUCT(('Marina 1'!G34:G39='Marina 1'!K34:K39)*1)+SUMPRODUCT(('Marina 1'!G43:G48='Marina 1'!K43:K48)*1)+SUMPRODUCT(('Marina 1'!G52:G57='Marina 1'!K52:K57)*1)+SUMPRODUCT(('Marina 1'!G61:G66='Marina 1'!K61:K66)*1)+SUMPRODUCT(('Marina 1'!G70:G75='Marina 1'!K70:K75)*1)+SUMPRODUCT(('Marina 1'!G79:G84='Marina 1'!K79:K84)*1)+SUMPRODUCT(('Marina 1'!G88:G93='Marina 1'!K88:K93)*1)+SUMPRODUCT(('Marina 1'!G97:G102='Marina 1'!K97:K102)*1)+SUMPRODUCT(('Marina 1'!G106:G111='Marina 1'!K106:K111)*1) -> 1 | E6: =SUM('Marina 1'!M:M)+Y74 -> 125 | F6: =RANK(E6,E:E,0) -> 13
B7: Ricco | C7: =SUMPRODUCT(('Ricco 1'!F7:F12='Ricco 1'!J7:J12)*1)+SUMPRODUCT(('Ricco 1'!F16:F21='Ricco 1'!J16:J21)*1)+SUMPRODUCT(('Ricco 1'!F25:F30='Ricco 1'!J25:J30)*1)+SUMPRODUCT(('Ricco 1'!F34:F39='Ricco 1'!J34:J39)*1)+SUMPRODUCT(('Ricco 1'!F43:F48='Ricco 1'!J43:J48)*1)+SUMPRODUCT(('Ricco 1'!F52:F57='Ricco 1'!J52:J57)*1)+SUMPRODUCT(('Ricco 1'!F61:F66='Ricco 1'!J61:J66)*1)+SUMPRODUCT(('Ricco 1'!F70:F75='Ricco 1'!J70:J75)*1)+SUMPRODUCT(('Ricco 1'!F79:F84='Ricco 1'!J79:J84)*1)+SUMPRODUCT(('Ricco 1'!F88:F93='Ricco 1'!J88:J93)*1)+SUMPRODUCT(('Ricco 1'!F97:F102='Ricco 1'!J97:J102)*1)+SUMPRODUCT(('Ricco 1'!F106:F111='Ricco 1'!J106:J111)*1) -> 1 | D7: =SUMPRODUCT(('Ricco 1'!G7:G12='Ricco 1'!K7:K12)*1)+SUMPRODUCT(('Ricco 1'!G16:G21='Ricco 1'!K16:K21)*1)+SUMPRODUCT(('Ricco 1'!G25:G30='Ricco 1'!K25:K30)*1)+SUMPRODUCT(('Ricco 1'!G34:G39='Ricco 1'!K34:K39)*1)+SUMPRODUCT(('Ricco 1'!G43:G48='Ricco 1'!K43:K48)*1)+SUMPRODUCT(('Ricco 1'!G52:G57='Ricco 1'!K52:K57)*1)+SUMPRODUCT(('Ricco 1'!G61:G66='Ricco 1'!K61:K66)*1)+SUMPRODUCT(('Ricco 1'!G70:G75='Ricco 1'!K70:K75)*1)+SUMPRODUCT(('Ricco 1'!G79:G84='Ricco 1'!K79:K84)*1)+SUMPRODUCT(('Ricco 1'!G88:G93='Ricco 1'!K88:K93)*1)+SUMPRODUCT(('Ricco 1'!G97:G102='Ricco 1'!K97:K102)*1)+SUMPRODUCT(('Ricco 1'!G106:G111='Ricco 1'!K106:K111)*1) -> 1 | E7: =SUM('Ricco 1'!M:M)+Y75 -> 150 | F7: =RANK(E7,E:E,0) -> 11
B8: Vero | C8: =SUMPRODUCT(('Vero 1'!F7:F12='Vero 1'!J7:J12)*1)+SUMPRODUCT(('Vero 1'!F16:F21='Vero 1'!J16:J21)*1)+SUMPRODUCT(('Vero 1'!F25:F30='Vero 1'!J25:J30)*1)+SUMPRODUCT(('Vero 1'!F34:F39='Vero 1'!J34:J39)*1)+SUMPRODUCT(('Vero 1'!F43:F48='Vero 1'!J43:J48)*1)+SUMPRODUCT(('Vero 1'!F52:F57='Vero 1'!J52:J57)*1)+SUMPRODUCT(('Vero 1'!F61:F66='Vero 1'!J61:J66)*1)+SUMPRODUCT(('Vero 1'!F70:F75='Vero 1'!J70:J75)*1)+SUMPRODUCT(('Vero 1'!F79:F84='Vero 1'!J79:J84)*1)+SUMPRODUCT(('Vero 1'!F88:F93='Vero 1'!J88:J93)*1)+SUMPRODUCT(('Vero 1'!F97:F102='Vero 1'!J97:J102)*1)+SUMPRODUCT(('Vero 1'!F106:F111='Vero 1'!J106:J111)*1) -> 3 | D8: =SUMPRODUCT(('Vero 1'!G7:G12='Vero 1'!K7:K12)*1)+SUMPRODUCT(('Vero 1'!G16:G21='Vero 1'!K16:K21)*1)+SUMPRODUCT(('Vero 1'!G25:G30='Vero 1'!K25:K30)*1)+SUMPRODUCT(('Vero 1'!G34:G39='Vero 1'!K34:K39)*1)+SUMPRODUCT(('Vero 1'!G43:G48='Vero 1'!K43:K48)*1)+SUMPRODUCT(('Vero 1'!G52:G57='Vero 1'!K52:K57)*1)+SUMPRODUCT(('Vero 1'!G61:G66='Vero 1'!K61:K66)*1)+SUMPRODUCT(('Vero 1'!G70:G75='Vero 1'!K70:K75)*1)+SUMPRODUCT(('Vero 1'!G79:G84='Vero 1'!K79:K84)*1)+SUMPRODUCT(('Vero 1'!G88:G93='Vero 1'!K88:K93)*1)+SUMPRODUCT(('Vero 1'!G97:G102='Vero 1'!K97:K102)*1)+SUMPRODUCT(('Vero 1'!G106:G111='Vero 1'!K106:K111)*1) -> 1 | E8: =SUM('Vero 1'!M:M)+Y76 -> 185 | F8: =RANK(E8,E:E,0) -> 7
B9: Hugo C. | C9: =SUMPRODUCT(('Hugo 1'!F7:F12='Hugo 1'!J7:J12)*1)+SUMPRODUCT(('Hugo 1'!F16:F21='Hugo 1'!J16:J21)*1)+SUMPRODUCT(('Hugo 1'!F25:F30='Hugo 1'!J25:J30)*1)+SUMPRODUCT(('Hugo 1'!F34:F39='Hugo 1'!J34:J39)*1)+SUMPRODUCT(('Hugo 1'!F43:F48='Hugo 1'!J43:J48)*1)+SUMPRODUCT(('Hugo 1'!F52:F57='Hugo 1'!J52:J57)*1)+SUMPRODUCT(('Hugo 1'!F61:F66='Hugo 1'!J61:J66)*1)+SUMPRODUCT(('Hugo 1'!F70:F75='Hugo 1'!J70:J75)*1)+SUMPRODUCT(('Hugo 1'!F79:F84='Hugo 1'!J79:J84)*1)+SUMPRODUCT(('Hugo 1'!F88:F93='Hugo 1'!J88:J93)*1)+SUMPRODUCT(('Hugo 1'!F97:F102='Hugo 1'!J97:J102)*1)+SUMPRODUCT(('Hugo 1'!F106:F111='Hugo 1'!J106:J111)*1) -> 2 | D9: =SUMPRODUCT(('Hugo 1'!G7:G12='Hugo 1'!K7:K12)*1)+SUMPRODUCT(('Hugo 1'!G16:G21='Hugo 1'!K16:K21)*1)+SUMPRODUCT(('Hugo 1'!G25:G30='Hugo 1'!K25:K30)*1)+SUMPRODUCT(('Hugo 1'!G34:G39='Hugo 1'!K34:K39)*1)+SUMPRODUCT(('Hugo 1'!G43:G48='Hugo 1'!K43:K48)*1)+SUMPRODUCT(('Hugo 1'!G52:G57='Hugo 1'!K52:K57)*1)+SUMPRODUCT(('Hugo 1'!G61:G66='Hugo 1'!K61:K66)*1)+SUMPRODUCT(('Hugo 1'!G70:G75='Hugo 1'!K70:K75)*1)+SUMPRODUCT(('Hugo 1'!G79:G84='Hugo 1'!K79:K84)*1)+SUMPRODUCT(('Hugo 1'!G88:G93='Hugo 1'!K88:K93)*1)+SUMPRODUCT(('Hugo 1'!G97:G102='Hugo 1'!K97:K102)*1)+SUMPRODUCT(('Hugo 1'!G106:G111='Hugo 1'!K106:K111)*1) -> 0 | E9: =SUM('Hugo 1'!M:M)+Y77 -> 75 | F9: =RANK(E9,E:E,0) -> 22
B10: Jeje | C10: =SUMPRODUCT(('Jeje 1'!F7:F12='Jeje 1'!J7:J12)*1)+SUMPRODUCT(('Jeje 1'!F16:F21='Jeje 1'!J16:J21)*1)+SUMPRODUCT(('Jeje 1'!F25:F30='Jeje 1'!J25:J30)*1)+SUMPRODUCT(('Jeje 1'!F34:F39='Jeje 1'!J34:J39)*1)+SUMPRODUCT(('Jeje 1'!F43:F48='Jeje 1'!J43:J48)*1)+SUMPRODUCT(('Jeje 1'!F52:F57='Jeje 1'!J52:J57)*1)+SUMPRODUCT(('Jeje 1'!F61:F66='Jeje 1'!J61:J66)*1)+SUMPRODUCT(('Jeje 1'!F70:F75='Jeje 1'!J70:J75)*1)+SUMPRODUCT(('Jeje 1'!F79:F84='Jeje 1'!J79:J84)*1)+SUMPRODUCT(('Jeje 1'!F88:F93='Jeje 1'!J88:J93)*1)+SUMPRODUCT(('Jeje 1'!F97:F102='Jeje 1'!J97:J102)*1)+SUMPRODUCT(('Jeje 1'!F106:F111='Jeje 1'!J106:J111)*1) -> 3 | D10: =SUMPRODUCT(('Jeje 1'!G7:G12='Jeje 1'!K7:K12)*1)+SUMPRODUCT(('Jeje 1'!G16:G21='Jeje 1'!K16:K21)*1)+SUMPRODUCT(('Jeje 1'!G25:G30='Jeje 1'!K25:K30)*1)+SUMPRODUCT(('Jeje 1'!G34:G39='Jeje 1'!K34:K39)*1)+SUMPRODUCT(('Jeje 1'!G43:G48='Jeje 1'!K43:K48)*1)+SUMPRODUCT(('Jeje 1'!G52:G57='Jeje 1'!K52:K57)*1)+SUMPRODUCT(('Jeje 1'!G61:G66='Jeje 1'!K61:K66)*1)+SUMPRODUCT(('Jeje 1'!G70:G75='Jeje 1'!K70:K75)*1)+SUMPRODUCT(('Jeje 1'!G79:G84='Jeje 1'!K79:K84)*1)+SUMPRODUCT(('Jeje 1'!G88:G93='Jeje 1'!K88:K93)*1)+SUMPRODUCT(('Jeje 1'!G97:G102='Jeje 1'!K97:K102)*1)+SUMPRODUCT(('Jeje 1'!G106:G111='Jeje 1'!K106:K111)*1) -> 1 | E10: =SUM('Jeje 1'!M:M)+Y78 -> 235 | F10: =RANK(E10,E:E,0) -> 3
B11: Laura | C11: =SUMPRODUCT(('Laura 1'!F7:F12='Laura 1'!J7:J12)*1)+SUMPRODUCT(('Laura 1'!F16:F21='Laura 1'!J16:J21)*1)+SUMPRODUCT(('Laura 1'!F25:F30='Laura 1'!J25:J30)*1)+SUMPRODUCT(('Laura 1'!F34:F39='Laura 1'!J34:J39)*1)+SUMPRODUCT(('Laura 1'!F43:F48='Laura 1'!J43:J48)*1)+SUMPRODUCT(('Laura 1'!F52:F57='Laura 1'!J52:J57)*1)+SUMPRODUCT(('Laura 1'!F61:F66='Laura 1'!J61:J66)*1)+SUMPRODUCT(('Laura 1'!F70:F75='Laura 1'!J70:J75)*1)+SUMPRODUCT(('Laura 1'!F79:F84='Laura 1'!J79:J84)*1)+SUMPRODUCT(('Laura 1'!F88:F93='Laura 1'!J88:J93)*1)+SUMPRODUCT(('Laura 1'!F97:F102='Laura 1'!J97:J102)*1)+SUMPRODUCT(('Laura 1'!F106:F111='Laura 1'!J106:J111)*1) -> 2 | D11: =SUMPRODUCT(('Laura 1'!G7:G12='Laura 1'!K7:K12)*1)+SUMPRODUCT(('Laura 1'!G16:G21='Laura 1'!K16:K21)*1)+SUMPRODUCT(('Laura 1'!G25:G30='Laura 1'!K25:K30)*1)+SUMPRODUCT(('Laura 1'!G34:G39='Laura 1'!K34:K39)*1)+SUMPRODUCT(('Laura 1'!G43:G48='Laura 1'!K43:K48)*1)+SUMPRODUCT(('Laura 1'!G52:G57='Laura 1'!K52:K57)*1)+SUMPRODUCT(('Laura 1'!G61:G66='Laura 1'!K61:K66)*1)+SUMPRODUCT(('Laura 1'!G70:G75='Laura 1'!K70:K75)*1)+SUMPRODUCT(('Laura 1'!G79:G84='Laura 1'!K79:K84)*1)+SUMPRODUCT(('Laura 1'!G88:G93='Laura 1'!K88:K93)*1)+SUMPRODUCT(('Laura 1'!G97:G102='Laura 1'!K97:K102)*1)+SUMPRODUCT(('Jeje 1'!G106:G111='Jeje 1'!K106:K111)*1) -> 1 | E11: =SUM('Laura 1'!M:M)+Y79 -> 125 | F11: =RANK(E11,E:E,0) -> 13
B12: Paco | C12: =SUMPRODUCT(('Paco 1'!F7:F12='Paco 1'!J7:J12)*1)+SUMPRODUCT(('Paco 1'!F16:F21='Paco 1'!J16:J21)*1)+SUMPRODUCT(('Paco 1'!F25:F30='Paco 1'!J25:J30)*1)+SUMPRODUCT(('Paco 1'!F34:F39='Paco 1'!J34:J39)*1)+SUMPRODUCT(('Paco 1'!F43:F48='Paco 1'!J43:J48)*1)+SUMPRODUCT(('Paco 1'!F52:F57='Paco 1'!J52:J57)*1)+SUMPRODUCT(('Paco 1'!F61:F66='Paco 1'!J61:J66)*1)+SUMPRODUCT(('Paco 1'!F70:F75='Paco 1'!J70:J75)*1)+SUMPRODUCT(('Paco 1'!F79:F84='Paco 1'!J79:J84)*1)+SUMPRODUCT(('Paco 1'!F88:F93='Paco 1'!J88:J93)*1)+SUMPRODUCT(('Paco 1'!F97:F102='Paco 1'!J97:J102)*1)+SUMPRODUCT(('Paco 1'!F106:F111='Paco 1'!J106:J111)*1) -> 3 | D12: =SUMPRODUCT(('Paco 1'!G7:G12='Paco 1'!K7:K12)*1)+SUMPRODUCT(('Paco 1'!G16:G21='Paco 1'!K16:K21)*1)+SUMPRODUCT(('Paco 1'!G25:G30='Paco 1'!K25:K30)*1)+SUMPRODUCT(('Paco 1'!G34:G39='Paco 1'!K34:K39)*1)+SUMPRODUCT(('Paco 1'!G43:G48='Paco 1'!K43:K48)*1)+SUMPRODUCT(('Paco 1'!G52:G57='Paco 1'!K52:K57)*1)+SUMPRODUCT(('Paco 1'!G61:G66='Paco 1'!K61:K66)*1)+SUMPRODUCT(('Paco 1'!G70:G75='Paco 1'!K70:K75)*1)+SUMPRODUCT(('Paco 1'!G79:G84='Paco 1'!K79:K84)*1)+SUMPRODUCT(('Paco 1'!G88:G93='Paco 1'!K88:K93)*1)+SUMPRODUCT(('Paco 1'!G97:G102='Paco 1'!K97:K102)*1)+SUMPRODUCT(('Paco 1'!G106:G111='Paco 1'!K106:K111)*1) -> 0 | E12: =SUM('Paco 1'!M:M)+Y80 -> 100 | F12: =RANK(E12,E:E,0) -> 17
B13: Cyrille | C13: =SUMPRODUCT(('Cyrille 1'!F7:F12='Cyrille 1'!J7:J12)*1)+SUMPRODUCT(('Cyrille 1'!F16:F21='Cyrille 1'!J16:J21)*1)+SUMPRODUCT(('Cyrille 1'!F25:F30='Cyrille 1'!J25:J30)*1)+SUMPRODUCT(('Cyrille 1'!F34:F39='Cyrille 1'!J34:J39)*1)+SUMPRODUCT(('Cyrille 1'!F43:F48='Cyrille 1'!J43:J48)*1)+SUMPRODUCT(('Cyrille 1'!F52:F57='Cyrille 1'!J52:J57)*1)+SUMPRODUCT(('Cyrille 1'!F61:F66='Cyrille 1'!J61:J66)*1)+SUMPRODUCT(('Cyrille 1'!F70:F75='Cyrille 1'!J70:J75)*1)+SUMPRODUCT(('Cyrille 1'!F79:F84='Cyrille 1'!J79:J84)*1)+SUMPRODUCT(('Cyrille 1'!F88:F93='Cyrille 1'!J88:J93)*1)+SUMPRODUCT(('Cyrille 1'!F97:F102='Cyrille 1'!J97:J102)*1)+SUMPRODUCT(('Cyrille 1'!F106:F111='Cyrille 1'!J106:J111)*1) -> 2 | D13: =SUMPRODUCT(('Cyrille 1'!G7:G12='Cyrille 1'!K7:K12)*1)+SUMPRODUCT(('Cyrille 1'!G16:G21='Cyrille 1'!K16:K21)*1)+SUMPRODUCT(('Cyrille 1'!G25:G30='Cyrille 1'!K25:K30)*1)+SUMPRODUCT(('Cyrille 1'!G34:G39='Cyrille 1'!K34:K39)*1)+SUMPRODUCT(('Cyrille 1'!G43:G48='Cyrille 1'!K43:K48)*1)+SUMPRODUCT(('Cyrille 1'!G52:G57='Cyrille 1'!K52:K57)*1)+SUMPRODUCT(('Cyrille 1'!G61:G66='Cyrille 1'!K61:K66)*1)+SUMPRODUCT(('Cyrille 1'!G70:G75='Cyrille 1'!K70:K75)*1)+SUMPRODUCT(('Cyrille 1'!G79:G84='Cyrille 1'!K79:K84)*1)+SUMPRODUCT(('Cyrille 1'!G88:G93='Cyrille 1'!K88:K93)*1)+SUMPRODUCT(('Cyrille 1'!G97:G102='Cyrille 1'!K97:K102)*1)+SUMPRODUCT(('Cyrille 1'!G106:G111='Cyrille 1'!K106:K111)*1) -> 0 | E13: =SUM('Cyrille 1'!M:M)+Y81 -> 50 | F13: =RANK(E13,E:E,0) -> 27
B14: Joris | C14: =SUMPRODUCT(('Joris 1'!F7:F12='Joris 1'!J7:J12)*1)+SUMPRODUCT(('Joris 1'!F16:F21='Joris 1'!J16:J21)*1)+SUMPRODUCT(('Joris 1'!F25:F30='Joris 1'!J25:J30)*1)+SUMPRODUCT(('Joris 1'!F34:F39='Joris 1'!J34:J39)*1)+SUMPRODUCT(('Joris 1'!F43:F48='Joris 1'!J43:J48)*1)+SUMPRODUCT(('Joris 1'!F52:F57='Joris 1'!J52:J57)*1)+SUMPRODUCT(('Joris 1'!F61:F66='Joris 1'!J61:J66)*1)+SUMPRODUCT(('Joris 1'!F70:F75='Joris 1'!J70:J75)*1)+SUMPRODUCT(('Joris 1'!F79:F84='Joris 1'!J79:J84)*1)+SUMPRODUCT(('Joris 1'!F88:F93='Joris 1'!J88:J93)*1)+SUMPRODUCT(('Joris 1'!F97:F102='Joris 1'!J97:J102)*1)+SUMPRODUCT(('Joris 1'!F106:F111='Joris 1'!J106:J111)*1) -> 3 | D14: =SUMPRODUCT(('Joris 1'!G7:G12='Joris 1'!K7:K12)*1)+SUMPRODUCT(('Joris 1'!G16:G21='Joris 1'!K16:K21)*1)+SUMPRODUCT(('Joris 1'!G25:G30='Joris 1'!K25:K30)*1)+SUMPRODUCT(('Joris 1'!G34:G39='Joris 1'!K34:K39)*1)+SUMPRODUCT(('Joris 1'!G43:G48='Joris 1'!K43:K48)*1)+SUMPRODUCT(('Joris 1'!G52:G57='Joris 1'!K52:K57)*1)+SUMPRODUCT(('Joris 1'!G61:G66='Joris 1'!K61:K66)*1)+SUMPRODUCT(('Joris 1'!G70:G75='Joris 1'!K70:K75)*1)+SUMPRODUCT(('Joris 1'!G79:G84='Joris 1'!K79:K84)*1)+SUMPRODUCT(('Joris 1'!G88:G93='Joris 1'!K88:K93)*1)+SUMPRODUCT(('Joris 1'!G97:G102='Joris 1'!K97:K102)*1)+SUMPRODUCT(('Joris 1'!G106:G111='Joris 1'!K106:K111)*1) -> 1 | E14: =SUM('Joris 1'!M:M)+Y82 -> 325 | F14: =RANK(E14,E:E,0) -> 1
B15: Léna | C15: =SUMPRODUCT(('Léna 1'!F7:F12='Léna 1'!J7:J12)*1)+SUMPRODUCT(('Léna 1'!F16:F21='Léna 1'!J16:J21)*1)+SUMPRODUCT(('Léna 1'!F25:F30='Léna 1'!J25:J30)*1)+SUMPRODUCT(('Léna 1'!F34:F39='Léna 1'!J34:J39)*1)+SUMPRODUCT(('Léna 1'!F43:F48='Léna 1'!J43:J48)*1)+SUMPRODUCT(('Léna 1'!F52:F57='Léna 1'!J52:J57)*1)+SUMPRODUCT(('Léna 1'!F61:F66='Léna 1'!J61:J66)*1)+SUMPRODUCT(('Léna 1'!F70:F75='Léna 1'!J70:J75)*1)+SUMPRODUCT(('Léna 1'!F79:F84='Léna 1'!J79:J84)*1)+SUMPRODUCT(('Léna 1'!F88:F93='Léna 1'!J88:J93)*1)+SUMPRODUCT(('Léna 1'!F97:F102='Léna 1'!J97:J102)*1)+SUMPRODUCT(('Léna 1'!F106:F111='Léna 1'!J106:J111)*1) -> 2 | D15: =SUMPRODUCT(('Léna 1'!G7:G12='Léna 1'!K7:K12)*1)+SUMPRODUCT(('Léna 1'!G16:G21='Léna 1'!K16:K21)*1)+SUMPRODUCT(('Léna 1'!G25:G30='Léna 1'!K25:K30)*1)+SUMPRODUCT(('Léna 1'!G34:G39='Léna 1'!K34:K39)*1)+SUMPRODUCT(('Léna 1'!G43:G48='Léna 1'!K43:K48)*1)+SUMPRODUCT(('Léna 1'!G52:G57='Léna 1'!K52:K57)*1)+SUMPRODUCT(('Léna 1'!G61:G66='Léna 1'!K61:K66)*1)+SUMPRODUCT(('Léna 1'!G70:G75='Léna 1'!K70:K75)*1)+SUMPRODUCT(('Léna 1'!G79:G84='Léna 1'!K79:K84)*1)+SUMPRODUCT(('Léna 1'!G88:G93='Léna 1'!K88:K93)*1)+SUMPRODUCT(('Léna 1'!G97:G102='Léna 1'!K97:K102)*1)+SUMPRODUCT(('Léna 1'!G106:G111='Léna 1'!K106:K111)*1) -> 1 | E15: =SUM('Léna 1'!M:M)+Y83 -> 175 | F15: =RANK(E15,E:E,0) -> 8
B16: Goyt | C16: =SUMPRODUCT(('Goyt 1'!F7:F12='Goyt 1'!J7:J12)*1)+SUMPRODUCT(('Goyt 1'!F16:F21='Goyt 1'!J16:J21)*1)+SUMPRODUCT(('Goyt 1'!F25:F30='Goyt 1'!J25:J30)*1)+SUMPRODUCT(('Goyt 1'!F34:F39='Goyt 1'!J34:J39)*1)+SUMPRODUCT(('Goyt 1'!F43:F48='Goyt 1'!J43:J48)*1)+SUMPRODUCT(('Goyt 1'!F52:F57='Goyt 1'!J52:J57)*1)+SUMPRODUCT(('Goyt 1'!F61:F66='Goyt 1'!J61:J66)*1)+SUMPRODUCT(('Goyt 1'!F70:F75='Goyt 1'!J70:J75)*1)+SUMPRODUCT(('Goyt 1'!F79:F84='Goyt 1'!J79:J84)*1)+SUMPRODUCT(('Goyt 1'!F88:F93='Goyt 1'!J88:J93)*1)+SUMPRODUCT(('Goyt 1'!F97:F102='Goyt 1'!J97:J102)*1)+SUMPRODUCT(('Goyt 1'!F106:F111='Goyt 1'!J106:J111)*1) -> 3 | D16: =SUMPRODUCT(('Goyt 1'!G7:G12='Goyt 1'!K7:K12)*1)+SUMPRODUCT(('Goyt 1'!G16:G21='Goyt 1'!K16:K21)*1)+SUMPRODUCT(('Goyt 1'!G25:G30='Goyt 1'!K25:K30)*1)+SUMPRODUCT(('Goyt 1'!G34:G39='Goyt 1'!K34:K39)*1)+SUMPRODUCT(('Goyt 1'!G43:G48='Goyt 1'!K43:K48)*1)+SUMPRODUCT(('Goyt 1'!G52:G57='Goyt 1'!K52:K57)*1)+SUMPRODUCT(('Goyt 1'!G61:G66='Goyt 1'!K61:K66)*1)+SUMPRODUCT(('Goyt 1'!G70:G75='Goyt 1'!K70:K75)*1)+SUMPRODUCT(('Goyt 1'!G79:G84='Goyt 1'!K79:K84)*1)+SUMPRODUCT(('Goyt 1'!G88:G93='Goyt 1'!K88:K93)*1)+SUMPRODUCT(('Goyt 1'!G97:G102='Goyt 1'!K97:K102)*1)+SUMPRODUCT(('Goyt 1'!G106:G111='Goyt 1'!K106:K111)*1) -> 0 | E16: =SUM('Goyt 1'!M:M)+Y84 -> 200 | F16: =RANK(E16,E:E,0) -> 5
B17: Noé | C17: =SUMPRODUCT(('Noe 1'!F7:F12='Noe 1'!J7:J12)*1)+SUMPRODUCT(('Noe 1'!F16:F21='Noe 1'!J16:J21)*1)+SUMPRODUCT(('Noe 1'!F25:F30='Noe 1'!J25:J30)*1)+SUMPRODUCT(('Noe 1'!F34:F39='Noe 1'!J34:J39)*1)+SUMPRODUCT(('Noe 1'!F43:F48='Noe 1'!J43:J48)*1)+SUMPRODUCT(('Noe 1'!F52:F57='Noe 1'!J52:J57)*1)+SUMPRODUCT(('Noe 1'!F61:F66='Noe 1'!J61:J66)*1)+SUMPRODUCT(('Noe 1'!F70:F75='Noe 1'!J70:J75)*1)+SUMPRODUCT(('Noe 1'!F79:F84='Noe 1'!J79:J84)*1)+SUMPRODUCT(('Noe 1'!F88:F93='Noe 1'!J88:J93)*1)+SUMPRODUCT(('Noe 1'!F97:F102='Noe 1'!J97:J102)*1)+SUMPRODUCT(('Noe 1'!F106:F111='Noe 1'!J106:J111)*1) -> 2 | D17: =SUMPRODUCT(('Noe 1'!G7:G12='Noe 1'!K7:K12)*1)+SUMPRODUCT(('Noe 1'!G16:G21='Noe 1'!K16:K21)*1)+SUMPRODUCT(('Noe 1'!G25:G30='Noe 1'!K25:K30)*1)+SUMPRODUCT(('Noe 1'!G34:G39='Noe 1'!K34:K39)*1)+SUMPRODUCT(('Noe 1'!G43:G48='Noe 1'!K43:K48)*1)+SUMPRODUCT(('Noe 1'!G52:G57='Noe 1'!K52:K57)*1)+SUMPRODUCT(('Noe 1'!G61:G66='Noe 1'!K61:K66)*1)+SUMPRODUCT(('Noe 1'!G70:G75='Noe 1'!K70:K75)*1)+SUMPRODUCT(('Noe 1'!G79:G84='Noe 1'!K79:K84)*1)+SUMPRODUCT(('Noe 1'!G88:G93='Noe 1'!K88:K93)*1)+SUMPRODUCT(('Noe 1'!G97:G102='Noe 1'!K97:K102)*1)+SUMPRODUCT(('Noe 1'!G106:G111='Noe 1'!K106:K111)*1) -> 1 | E17: =SUM('Noe 1'!M:M)+Y85 -> 200 | F17: =RANK(E17,E:E,0) -> 5
B18: Clara | C18: =SUMPRODUCT(('Clara 1'!F7:F12='Clara 1'!J7:J12)*1)+SUMPRODUCT(('Clara 1'!F16:F21='Clara 1'!J16:J21)*1)+SUMPRODUCT(('Clara 1'!F25:F30='Clara 1'!J25:J30)*1)+SUMPRODUCT(('Clara 1'!F34:F39='Clara 1'!J34:J39)*1)+SUMPRODUCT(('Clara 1'!F43:F48='Clara 1'!J43:J48)*1)+SUMPRODUCT(('Clara 1'!F52:F57='Clara 1'!J52:J57)*1)+SUMPRODUCT(('Clara 1'!F61:F66='Clara 1'!J61:J66)*1)+SUMPRODUCT(('Clara 1'!F70:F75='Clara 1'!J70:J75)*1)+SUMPRODUCT(('Clara 1'!F79:F84='Clara 1'!J79:J84)*1)+SUMPRODUCT(('Clara 1'!F88:F93='Clara 1'!J88:J93)*1)+SUMPRODUCT(('Clara 1'!F97:F102='Clara 1'!J97:J102)*1)+SUMPRODUCT(('Clara 1'!F106:F111='Clara 1'!J106:J111)*1) -> 2 | D18: =SUMPRODUCT(('Clara 1'!G7:G12='Clara 1'!K7:K12)*1)+SUMPRODUCT(('Clara 1'!G16:G21='Clara 1'!K16:K21)*1)+SUMPRODUCT(('Clara 1'!G25:G30='Clara 1'!K25:K30)*1)+SUMPRODUCT(('Clara 1'!G34:G39='Clara 1'!K34:K39)*1)+SUMPRODUCT(('Clara 1'!G43:G48='Clara 1'!K43:K48)*1)+SUMPRODUCT(('Clara 1'!G52:G57='Clara 1'!K52:K57)*1)+SUMPRODUCT(('Clara 1'!G61:G66='Clara 1'!K61:K66)*1)+SUMPRODUCT(('Clara 1'!G70:G75='Clara 1'!K70:K75)*1)+SUMPRODUCT(('Clara 1'!G79:G84='Clara 1'!K79:K84)*1)+SUMPRODUCT(('Clara 1'!G88:G93='Clara 1'!K88:K93)*1)+SUMPRODUCT(('Clara 1'!G97:G102='Clara 1'!K97:K102)*1)+SUMPRODUCT(('Clara 1'!G106:G111='Clara 1'!K106:K111)*1) -> 1 | E18: =SUM('Clara 1'!M:M)+Y86 -> 125 | F18: =RANK(E18,E:E,0) -> 13
B19: Erwan | C19: =SUMPRODUCT(('Erwan 1'!F7:F12='Erwan 1'!J7:J12)*1)+SUMPRODUCT(('Erwan 1'!F16:F21='Erwan 1'!J16:J21)*1)+SUMPRODUCT(('Erwan 1'!F25:F30='Erwan 1'!J25:J30)*1)+SUMPRODUCT(('Erwan 1'!F34:F39='Erwan 1'!J34:J39)*1)+SUMPRODUCT(('Erwan 1'!F43:F48='Erwan 1'!J43:J48)*1)+SUMPRODUCT(('Erwan 1'!F52:F57='Erwan 1'!J52:J57)*1)+SUMPRODUCT(('Erwan 1'!F61:F66='Erwan 1'!J61:J66)*1)+SUMPRODUCT(('Erwan 1'!F70:F75='Erwan 1'!J70:J75)*1)+SUMPRODUCT(('Erwan 1'!F79:F84='Erwan 1'!J79:J84)*1)+SUMPRODUCT(('Erwan 1'!F88:F93='Erwan 1'!J88:J93)*1)+SUMPRODUCT(('Erwan 1'!F97:F102='Erwan 1'!J97:J102)*1)+SUMPRODUCT(('Erwan 1'!F106:F111='Erwan 1'!J106:J111)*1) -> 2 | D19: =SUMPRODUCT(('Erwan 1'!G7:G12='Erwan 1'!K7:K12)*1)+SUMPRODUCT(('Erwan 1'!G16:G21='Erwan 1'!K16:K21)*1)+SUMPRODUCT(('Erwan 1'!G25:G30='Erwan 1'!K25:K30)*1)+SUMPRODUCT(('Erwan 1'!G34:G39='Erwan 1'!K34:K39)*1)+SUMPRODUCT(('Erwan 1'!G43:G48='Erwan 1'!K43:K48)*1)+SUMPRODUCT(('Erwan 1'!G52:G57='Erwan 1'!K52:K57)*1)+SUMPRODUCT(('Erwan 1'!G61:G66='Erwan 1'!K61:K66)*1)+SUMPRODUCT(('Erwan 1'!G70:G75='Erwan 1'!K70:K75)*1)+SUMPRODUCT(('Erwan 1'!G79:G84='Erwan 1'!K79:K84)*1)+SUMPRODUCT(('Erwan 1'!G88:G93='Erwan 1'!K88:K93)*1)+SUMPRODUCT(('Erwan 1'!G97:G102='Erwan 1'!K97:K102)*1)+SUMPRODUCT(('Erwan 1'!G106:G111='Erwan 1'!K106:K111)*1) -> 0 | E19: =SUM('Erwan 1'!M:M)+Y87 -> 100 | F19: =RANK(E19,E:E,0) -> 17
B20: Micka | C20: =SUMPRODUCT(('Micka 1'!F7:F12='Micka 1'!J7:J12)*1)+SUMPRODUCT(('Micka 1'!F16:F21='Micka 1'!J16:J21)*1)+SUMPRODUCT(('Micka 1'!F25:F30='Micka 1'!J25:J30)*1)+SUMPRODUCT(('Micka 1'!F34:F39='Micka 1'!J34:J39)*1)+SUMPRODUCT(('Micka 1'!F43:F48='Micka 1'!J43:J48)*1)+SUMPRODUCT(('Micka 1'!F52:F57='Micka 1'!J52:J57)*1)+SUMPRODUCT(('Micka 1'!F61:F66='Micka 1'!J61:J66)*1)+SUMPRODUCT(('Micka 1'!F70:F75='Micka 1'!J70:J75)*1)+SUMPRODUCT(('Micka 1'!F79:F84='Micka 1'!J79:J84)*1)+SUMPRODUCT(('Micka 1'!F88:F93='Micka 1'!J88:J93)*1)+SUMPRODUCT(('Micka 1'!F97:F102='Micka 1'!J97:J102)*1)+SUMPRODUCT(('Micka 1'!F106:F111='Micka 1'!J106:J111)*1) -> 2 | D20: =SUMPRODUCT(('Micka 1'!G7:G12='Micka 1'!K7:K12)*1)+SUMPRODUCT(('Micka 1'!G16:G21='Micka 1'!K16:K21)*1)+SUMPRODUCT(('Micka 1'!G25:G30='Micka 1'!K25:K30)*1)+SUMPRODUCT(('Micka 1'!G34:G39='Micka 1'!K34:K39)*1)+SUMPRODUCT(('Micka 1'!G43:G48='Micka 1'!K43:K48)*1)+SUMPRODUCT(('Micka 1'!G52:G57='Micka 1'!K52:K57)*1)+SUMPRODUCT(('Micka 1'!G61:G66='Micka 1'!K61:K66)*1)+SUMPRODUCT(('Micka 1'!G70:G75='Micka 1'!K70:K75)*1)+SUMPRODUCT(('Micka 1'!G79:G84='Micka 1'!K79:K84)*1)+SUMPRODUCT(('Micka 1'!G88:G93='Micka 1'!K88:K93)*1)+SUMPRODUCT(('Micka 1'!G97:G102='Micka 1'!K97:K102)*1)+SUMPRODUCT(('Micka 1'!G106:G111='Micka 1'!K106:K111)*1) -> 0 | E20: =SUM('Micka 1'!M:M)+Y88 -> 100 | F20: =RANK(E20,E:E,0) -> 17
B21: Greg | C21: =SUMPRODUCT(('Greg 1'!F7:F12='Greg 1'!J7:J12)*1)+SUMPRODUCT(('Greg 1'!F16:F21='Greg 1'!J16:J21)*1)+SUMPRODUCT(('Greg 1'!F25:F30='Greg 1'!J25:J30)*1)+SUMPRODUCT(('Greg 1'!F34:F39='Greg 1'!J34:J39)*1)+SUMPRODUCT(('Greg 1'!F43:F48='Greg 1'!J43:J48)*1)+SUMPRODUCT(('Greg 1'!F52:F57='Greg 1'!J52:J57)*1)+SUMPRODUCT(('Greg 1'!F61:F66='Greg 1'!J61:J66)*1)+SUMPRODUCT(('Greg 1'!F70:F75='Greg 1'!J70:J75)*1)+SUMPRODUCT(('Greg 1'!F79:F84='Greg 1'!J79:J84)*1)+SUMPRODUCT(('Greg 1'!F88:F93='Greg 1'!J88:J93)*1)+SUMPRODUCT(('Greg 1'!F97:F102='Greg 1'!J97:J102)*1)+SUMPRODUCT(('Greg 1'!F106:F111='Greg 1'!J106:J111)*1) -> 2 | D21: =SUMPRODUCT(('Greg 1'!G7:G12='Greg 1'!K7:K12)*1)+SUMPRODUCT(('Greg 1'!G16:G21='Greg 1'!K16:K21)*1)+SUMPRODUCT(('Greg 1'!G25:G30='Greg 1'!K25:K30)*1)+SUMPRODUCT(('Greg 1'!G34:G39='Greg 1'!K34:K39)*1)+SUMPRODUCT(('Greg 1'!G43:G48='Greg 1'!K43:K48)*1)+SUMPRODUCT(('Greg 1'!G52:G57='Greg 1'!K52:K57)*1)+SUMPRODUCT(('Greg 1'!G61:G66='Greg 1'!K61:K66)*1)+SUMPRODUCT(('Greg 1'!G70:G75='Greg 1'!K70:K75)*1)+SUMPRODUCT(('Greg 1'!G79:G84='Greg 1'!K79:K84)*1)+SUMPRODUCT(('Greg 1'!G88:G93='Greg 1'!K88:K93)*1)+SUMPRODUCT(('Greg 1'!G97:G102='Greg 1'!K97:K102)*1)+SUMPRODUCT(('Greg 1'!G106:G111='Greg 1'!K106:K111)*1) -> 0 | E21: =SUM('Greg 1'!M:M)+Y89 -> 50 | F21: =RANK(E21,E:E,0) -> 27
B22: Kalash | C22: =SUMPRODUCT(('Kalash 1'!F7:F12='Kalash 1'!J7:J12)*1)+SUMPRODUCT(('Kalash 1'!F16:F21='Kalash 1'!J16:J21)*1)+SUMPRODUCT(('Kalash 1'!F25:F30='Kalash 1'!J25:J30)*1)+SUMPRODUCT(('Kalash 1'!F34:F39='Kalash 1'!J34:J39)*1)+SUMPRODUCT(('Kalash 1'!F43:F48='Kalash 1'!J43:J48)*1)+SUMPRODUCT(('Kalash 1'!F52:F57='Kalash 1'!J52:J57)*1)+SUMPRODUCT(('Kalash 1'!F61:F66='Kalash 1'!J61:J66)*1)+SUMPRODUCT(('Kalash 1'!F70:F75='Kalash 1'!J70:J75)*1)+SUMPRODUCT(('Kalash 1'!F79:F84='Kalash 1'!J79:J84)*1)+SUMPRODUCT(('Kalash 1'!F88:F93='Kalash 1'!J88:J93)*1)+SUMPRODUCT(('Kalash 1'!F97:F102='Kalash 1'!J97:J102)*1)+SUMPRODUCT(('Kalash 1'!F106:F111='Kalash 1'!J106:J111)*1) -> 0 | D22: =SUMPRODUCT(('Kalash 1'!G7:G12='Kalash 1'!K7:K12)*1)+SUMPRODUCT(('Kalash 1'!G16:G21='Kalash 1'!K16:K21)*1)+SUMPRODUCT(('Kalash 1'!G25:G30='Kalash 1'!K25:K30)*1)+SUMPRODUCT(('Kalash 1'!G34:G39='Kalash 1'!K34:K39)*1)+SUMPRODUCT(('Kalash 1'!G43:G48='Kalash 1'!K43:K48)*1)+SUMPRODUCT(('Kalash 1'!G52:G57='Kalash 1'!K52:K57)*1)+SUMPRODUCT(('Kalash 1'!G61:G66='Kalash 1'!K61:K66)*1)+SUMPRODUCT(('Kalash 1'!G70:G75='Kalash 1'!K70:K75)*1)+SUMPRODUCT(('Kalash 1'!G79:G84='Kalash 1'!K79:K84)*1)+SUMPRODUCT(('Kalash 1'!G88:G93='Kalash 1'!K88:K93)*1)+SUMPRODUCT(('Kalash 1'!G97:G102='Kalash 1'!K97:K102)*1)+SUMPRODUCT(('Kalash 1'!G106:G111='Kalash 1'!K106:K111)*1) -> 0 | E22: =SUM('Kalash 1'!M:M)+Y90 -> 0 | F22: =RANK(E22,E:E,0) -> 51
B23: Jess | C23: =SUMPRODUCT(('Jess 1'!F7:F12='Jess 1'!J7:J12)*1)+SUMPRODUCT(('Jess 1'!F16:F21='Jess 1'!J16:J21)*1)+SUMPRODUCT(('Jess 1'!F25:F30='Jess 1'!J25:J30)*1)+SUMPRODUCT(('Jess 1'!F34:F39='Jess 1'!J34:J39)*1)+SUMPRODUCT(('Jess 1'!F43:F48='Jess 1'!J43:J48)*1)+SUMPRODUCT(('Jess 1'!F52:F57='Jess 1'!J52:J57)*1)+SUMPRODUCT(('Jess 1'!F61:F66='Jess 1'!J61:J66)*1)+SUMPRODUCT(('Jess 1'!F70:F75='Jess 1'!J70:J75)*1)+SUMPRODUCT(('Jess 1'!F79:F84='Jess 1'!J79:J84)*1)+SUMPRODUCT(('Jess 1'!F88:F93='Jess 1'!J88:J93)*1)+SUMPRODUCT(('Jess 1'!F97:F102='Jess 1'!J97:J102)*1)+SUMPRODUCT(('Jess 1'!F106:F111='Jess 1'!J106:J111)*1) -> 3 | D23: =SUMPRODUCT(('Jess 1'!G7:G12='Jess 1'!K7:K12)*1)+SUMPRODUCT(('Jess 1'!G16:G21='Jess 1'!K16:K21)*1)+SUMPRODUCT(('Jess 1'!G25:G30='Jess 1'!K25:K30)*1)+SUMPRODUCT(('Jess 1'!G34:G39='Jess 1'!K34:K39)*1)+SUMPRODUCT(('Jess 1'!G43:G48='Jess 1'!K43:K48)*1)+SUMPRODUCT(('Jess 1'!G52:G57='Jess 1'!K52:K57)*1)+SUMPRODUCT(('Jess 1'!G61:G66='Jess 1'!K61:K66)*1)+SUMPRODUCT(('Jess 1'!G70:G75='Jess 1'!K70:K75)*1)+SUMPRODUCT(('Jess 1'!G79:G84='Jess 1'!K79:K84)*1)+SUMPRODUCT(('Jess 1'!G88:G93='Jess 1'!K88:K93)*1)+SUMPRODUCT(('Jess 1'!G97:G102='Jess 1'!K97:K102)*1)+SUMPRODUCT(('Jess 1'!G106:G111='Jess 1'!K106:K111)*1) -> 1 | E23: =SUM('Jess 1'!M:M)+Y91 -> 260 | F23: =RANK(E23,E:E,0) -> 2
B24: Steph | C24: =SUMPRODUCT(('Steph 1'!F7:F12='Steph 1'!J7:J12)*1)+SUMPRODUCT(('Steph 1'!F16:F21='Steph 1'!J16:J21)*1)+SUMPRODUCT(('Steph 1'!F25:F30='Steph 1'!J25:J30)*1)+SUMPRODUCT(('Steph 1'!F34:F39='Steph 1'!J34:J39)*1)+SUMPRODUCT(('Steph 1'!F43:F48='Steph 1'!J43:J48)*1)+SUMPRODUCT(('Steph 1'!F52:F57='Steph 1'!J52:J57)*1)+SUMPRODUCT(('Steph 1'!F61:F66='Steph 1'!J61:J66)*1)+SUMPRODUCT(('Steph 1'!F70:F75='Steph 1'!J70:J75)*1)+SUMPRODUCT(('Steph 1'!F79:F84='Steph 1'!J79:J84)*1)+SUMPRODUCT(('Steph 1'!F88:F93='Steph 1'!J88:J93)*1)+SUMPRODUCT(('Steph 1'!F97:F102='Steph 1'!J97:J102)*1)+SUMPRODUCT(('Steph 1'!F106:F111='Steph 1'!J106:J111)*1) -> 2 | D24: =SUMPRODUCT(('Steph 1'!G7:G12='Steph 1'!K7:K12)*1)+SUMPRODUCT(('Steph 1'!G16:G21='Steph 1'!K16:K21)*1)+SUMPRODUCT(('Steph 1'!G25:G30='Steph 1'!K25:K30)*1)+SUMPRODUCT(('Steph 1'!G34:G39='Steph 1'!K34:K39)*1)+SUMPRODUCT(('Steph 1'!G43:G48='Steph 1'!K43:K48)*1)+SUMPRODUCT(('Steph 1'!G52:G57='Steph 1'!K52:K57)*1)+SUMPRODUCT(('Steph 1'!G61:G66='Steph 1'!K61:K66)*1)+SUMPRODUCT(('Steph 1'!G70:G75='Steph 1'!K70:K75)*1)+SUMPRODUCT(('Steph 1'!G79:G84='Steph 1'!K79:K84)*1)+SUMPRODUCT(('Steph 1'!G88:G93='Steph 1'!K88:K93)*1)+SUMPRODUCT(('Steph 1'!G97:G102='Steph 1'!K97:K102)*1)+SUMPRODUCT(('Steph 1'!G106:G111='Steph 1'!K106:K111)*1) -> 1 | E24: =SUM('Steph 1'!M:M)+Y92 -> 175 | F24: =RANK(E24,E:E,0) -> 8
B25: Chloé | C25: =SUMPRODUCT(('Chloé 1'!F7:F12='Chloé 1'!J7:J12)*1)+SUMPRODUCT(('Chloé 1'!F16:F21='Chloé 1'!J16:J21)*1)+SUMPRODUCT(('Chloé 1'!F25:F30='Chloé 1'!J25:J30)*1)+SUMPRODUCT(('Chloé 1'!F34:F39='Chloé 1'!J34:J39)*1)+SUMPRODUCT(('Chloé 1'!F43:F48='Chloé 1'!J43:J48)*1)+SUMPRODUCT(('Chloé 1'!F52:F57='Chloé 1'!J52:J57)*1)+SUMPRODUCT(('Chloé 1'!F61:F66='Chloé 1'!J61:J66)*1)+SUMPRODUCT(('Chloé 1'!F70:F75='Chloé 1'!J70:J75)*1)+SUMPRODUCT(('Chloé 1'!F79:F84='Chloé 1'!J79:J84)*1)+SUMPRODUCT(('Chloé 1'!F88:F93='Chloé 1'!J88:J93)*1)+SUMPRODUCT(('Chloé 1'!F97:F102='Chloé 1'!J97:J102)*1)+SUMPRODUCT(('Chloé 1'!F106:F111='Chloé 1'!J106:J111)*1) -> 2 | D25: =SUMPRODUCT(('Chloé 1'!G7:G12='Chloé 1'!K7:K12)*1)+SUMPRODUCT(('Chloé 1'!G16:G21='Chloé 1'!K16:K21)*1)+SUMPRODUCT(('Chloé 1'!G25:G30='Chloé 1'!K25:K30)*1)+SUMPRODUCT(('Chloé 1'!G34:G39='Chloé 1'!K34:K39)*1)+SUMPRODUCT(('Chloé 1'!G43:G48='Chloé 1'!K43:K48)*1)+SUMPRODUCT(('Chloé 1'!G52:G57='Chloé 1'!K52:K57)*1)+SUMPRODUCT(('Chloé 1'!G61:G66='Chloé 1'!K61:K66)*1)+SUMPRODUCT(('Chloé 1'!G70:G75='Chloé 1'!K70:K75)*1)+SUMPRODUCT(('Chloé 1'!G79:G84='Chloé 1'!K79:K84)*1)+SUMPRODUCT(('Chloé 1'!G88:G93='Chloé 1'!K88:K93)*1)+SUMPRODUCT(('Chloé 1'!G97:G102='Chloé 1'!K97:K102)*1)+SUMPRODUCT(('Chloé 1'!G106:G111='Chloé 1'!K106:K111)*1) -> 0 | E25: =SUM('Chloé 1'!M:M)+Y93 -> 125 | F25: =RANK(E25,E:E,0) -> 13
B26: Mathys | C26: =SUMPRODUCT(('Mathys 1'!F7:F12='Mathys 1'!J7:J12)*1)+SUMPRODUCT(('Mathys 1'!F16:F21='Mathys 1'!J16:J21)*1)+SUMPRODUCT(('Mathys 1'!F25:F30='Mathys 1'!J25:J30)*1)+SUMPRODUCT(('Mathys 1'!F34:F39='Mathys 1'!J34:J39)*1)+SUMPRODUCT(('Mathys 1'!F43:F48='Mathys 1'!J43:J48)*1)+SUMPRODUCT(('Mathys 1'!F52:F57='Mathys 1'!J52:J57)*1)+SUMPRODUCT(('Mathys 1'!F61:F66='Mathys 1'!J61:J66)*1)+SUMPRODUCT(('Mathys 1'!F70:F75='Mathys 1'!J70:J75)*1)+SUMPRODUCT(('Mathys 1'!F79:F84='Mathys 1'!J79:J84)*1)+SUMPRODUCT(('Mathys 1'!F88:F93='Mathys 1'!J88:J93)*1)+SUMPRODUCT(('Mathys 1'!F97:F102='Mathys 1'!J97:J102)*1)+SUMPRODUCT(('Mathys 1'!F106:F111='Mathys 1'!J106:J111)*1) -> 2 | D26: =SUMPRODUCT(('Mathys 1'!G7:G12='Mathys 1'!K7:K12)*1)+SUMPRODUCT(('Mathys 1'!G16:G21='Mathys 1'!K16:K21)*1)+SUMPRODUCT(('Mathys 1'!G25:G30='Mathys 1'!K25:K30)*1)+SUMPRODUCT(('Mathys 1'!G34:G39='Mathys 1'!K34:K39)*1)+SUMPRODUCT(('Mathys 1'!G43:G48='Mathys 1'!K43:K48)*1)+SUMPRODUCT(('Mathys 1'!G52:G57='Mathys 1'!K52:K57)*1)+SUMPRODUCT(('Mathys 1'!G61:G66='Mathys 1'!K61:K66)*1)+SUMPRODUCT(('Mathys 1'!G70:G75='Mathys 1'!K70:K75)*1)+SUMPRODUCT(('Mathys 1'!G79:G84='Mathys 1'!K79:K84)*1)+SUMPRODUCT(('Mathys 1'!G88:G93='Mathys 1'!K88:K93)*1)+SUMPRODUCT(('Mathys 1'!G97:G102='Mathys 1'!K97:K102)*1)+SUMPRODUCT(('Mathys 1'!G106:G111='Mathys 1'!K106:K111)*1) -> 1 | E26: =SUM('Mathys 1'!M:M)+Y94 -> 75 | F26: =RANK(E26,E:E,0) -> 22
B27: Aymeric | C27: =SUMPRODUCT(('Aymeric 1'!F7:F12='Aymeric 1'!J7:J12)*1)+SUMPRODUCT(('Aymeric 1'!F16:F21='Aymeric 1'!J16:J21)*1)+SUMPRODUCT(('Aymeric 1'!F25:F30='Aymeric 1'!J25:J30)*1)+SUMPRODUCT(('Aymeric 1'!F34:F39='Aymeric 1'!J34:J39)*1)+SUMPRODUCT(('Aymeric 1'!F43:F48='Aymeric 1'!J43:J48)*1)+SUMPRODUCT(('Aymeric 1'!F52:F57='Aymeric 1'!J52:J57)*1)+SUMPRODUCT(('Aymeric 1'!F61:F66='Aymeric 1'!J61:J66)*1)+SUMPRODUCT(('Aymeric 1'!F70:F75='Aymeric 1'!J70:J75)*1)+SUMPRODUCT(('Aymeric 1'!F79:F84='Aymeric 1'!J79:J84)*1)+SUMPRODUCT(('Aymeric 1'!F88:F93='Aymeric 1'!J88:J93)*1)+SUMPRODUCT(('Aymeric 1'!F97:F102='Aymeric 1'!J97:J102)*1)+SUMPRODUCT(('Aymeric 1'!F106:F111='Aymeric 1'!J106:J111)*1) -> 3 | D27: =SUMPRODUCT(('Aymeric 1'!G7:G12='Aymeric 1'!K7:K12)*1)+SUMPRODUCT(('Aymeric 1'!G16:G21='Aymeric 1'!K16:K21)*1)+SUMPRODUCT(('Aymeric 1'!G25:G30='Aymeric 1'!K25:K30)*1)+SUMPRODUCT(('Aymeric 1'!G34:G39='Aymeric 1'!K34:K39)*1)+SUMPRODUCT(('Aymeric 1'!G43:G48='Aymeric 1'!K43:K48)*1)+SUMPRODUCT(('Aymeric 1'!G52:G57='Aymeric 1'!K52:K57)*1)+SUMPRODUCT(('Aymeric 1'!G61:G66='Aymeric 1'!K61:K66)*1)+SUMPRODUCT(('Aymeric 1'!G70:G75='Aymeric 1'!K70:K75)*1)+SUMPRODUCT(('Aymeric 1'!G79:G84='Aymeric 1'!K79:K84)*1)+SUMPRODUCT(('Aymeric 1'!G88:G93='Aymeric 1'!K88:K93)*1)+SUMPRODUCT(('Aymeric 1'!G97:G102='Aymeric 1'!K97:K102)*1)+SUMPRODUCT(('Aymeric 1'!G106:G111='Aymeric 1'!K106:K111)*1) -> 1 | E27: =SUM('Aymeric 1'!M:M)+Y95 -> 225 | F27: =RANK(E27,E:E,0) -> 4
B28: Shervan | C28: =SUMPRODUCT(('Shervan 1'!F7:F12='Shervan 1'!J7:J12)*1)+SUMPRODUCT(('Shervan 1'!F16:F21='Shervan 1'!J16:J21)*1)+SUMPRODUCT(('Shervan 1'!F25:F30='Shervan 1'!J25:J30)*1)+SUMPRODUCT(('Shervan 1'!F34:F39='Shervan 1'!J34:J39)*1)+SUMPRODUCT(('Shervan 1'!F43:F48='Shervan 1'!J43:J48)*1)+SUMPRODUCT(('Shervan 1'!F52:F57='Shervan 1'!J52:J57)*1)+SUMPRODUCT(('Shervan 1'!F61:F66='Shervan 1'!J61:J66)*1)+SUMPRODUCT(('Shervan 1'!F70:F75='Shervan 1'!J70:J75)*1)+SUMPRODUCT(('Shervan 1'!F79:F84='Shervan 1'!J79:J84)*1)+SUMPRODUCT(('Shervan 1'!F88:F93='Shervan 1'!J88:J93)*1)+SUMPRODUCT(('Shervan 1'!F97:F102='Shervan 1'!J97:J102)*1)+SUMPRODUCT(('Shervan 1'!F106:F111='Shervan 1'!J106:J111)*1) -> 0 | D28: =SUMPRODUCT(('Shervan 1'!G7:G12='Shervan 1'!K7:K12)*1)+SUMPRODUCT(('Shervan 1'!G16:G21='Shervan 1'!K16:K21)*1)+SUMPRODUCT(('Shervan 1'!G25:G30='Shervan 1'!K25:K30)*1)+SUMPRODUCT(('Shervan 1'!G34:G39='Shervan 1'!K34:K39)*1)+SUMPRODUCT(('Shervan 1'!G43:G48='Shervan 1'!K43:K48)*1)+SUMPRODUCT(('Shervan 1'!G52:G57='Shervan 1'!K52:K57)*1)+SUMPRODUCT(('Shervan 1'!G61:G66='Shervan 1'!K61:K66)*1)+SUMPRODUCT(('Shervan 1'!G70:G75='Shervan 1'!K70:K75)*1)+SUMPRODUCT(('Shervan 1'!G79:G84='Shervan 1'!K79:K84)*1)+SUMPRODUCT(('Shervan 1'!G88:G93='Shervan 1'!K88:K93)*1)+SUMPRODUCT(('Shervan 1'!G97:G102='Shervan 1'!K97:K102)*1)+SUMPRODUCT(('Shervan 1'!G106:G111='Shervan 1'!K106:K111)*1) -> 0 | E28: =SUM('Shervan 1'!M:M)+Y96 -> 0 | F28: =RANK(E28,E:E,0) -> 51
B29: Nikola | C29: =SUMPRODUCT(('Nikola 1'!F7:F12='Nikola 1'!J7:J12)*1)+SUMPRODUCT(('Nikola 1'!F16:F21='Nikola 1'!J16:J21)*1)+SUMPRODUCT(('Nikola 1'!F25:F30='Nikola 1'!J25:J30)*1)+SUMPRODUCT(('Nikola 1'!F34:F39='Nikola 1'!J34:J39)*1)+SUMPRODUCT(('Nikola 1'!F43:F48='Nikola 1'!J43:J48)*1)+SUMPRODUCT(('Nikola 1'!F52:F57='Nikola 1'!J52:J57)*1)+SUMPRODUCT(('Nikola 1'!F61:F66='Nikola 1'!J61:J66)*1)+SUMPRODUCT(('Nikola 1'!F70:F75='Nikola 1'!J70:J75)*1)+SUMPRODUCT(('Nikola 1'!F79:F84='Nikola 1'!J79:J84)*1)+SUMPRODUCT(('Nikola 1'!F88:F93='Nikola 1'!J88:J93)*1)+SUMPRODUCT(('Nikola 1'!F97:F102='Nikola 1'!J97:J102)*1)+SUMPRODUCT(('Nikola 1'!F106:F111='Nikola 1'!J106:J111)*1) -> 2 | D29: =SUMPRODUCT(('Nikola 1'!G7:G12='Nikola 1'!K7:K12)*1)+SUMPRODUCT(('Nikola 1'!G16:G21='Nikola 1'!K16:K21)*1)+SUMPRODUCT(('Nikola 1'!G25:G30='Nikola 1'!K25:K30)*1)+SUMPRODUCT(('Nikola 1'!G34:G39='Nikola 1'!K34:K39)*1)+SUMPRODUCT(('Nikola 1'!G43:G48='Nikola 1'!K43:K48)*1)+SUMPRODUCT(('Nikola 1'!G52:G57='Nikola 1'!K52:K57)*1)+SUMPRODUCT(('Nikola 1'!G61:G66='Nikola 1'!K61:K66)*1)+SUMPRODUCT(('Nikola 1'!G70:G75='Nikola 1'!K70:K75)*1)+SUMPRODUCT(('Nikola 1'!G79:G84='Nikola 1'!K79:K84)*1)+SUMPRODUCT(('Nikola 1'!G88:G93='Nikola 1'!K88:K93)*1)+SUMPRODUCT(('Nikola 1'!G97:G102='Nikola 1'!K97:K102)*1)+SUMPRODUCT(('Nikola 1'!G106:G111='Nikola 1'!K106:K111)*1) -> 0 | E29: =SUM('Nikola 1'!M:M)+Y97 -> 50 | F29: =RANK(E29,E:E,0) -> 27
B30: Hugo O. | C30: =SUMPRODUCT(('Hugo.O 1'!F7:F12='Hugo.O 1'!J7:J12)*1)+SUMPRODUCT(('Hugo.O 1'!F16:F21='Hugo.O 1'!J16:J21)*1)+SUMPRODUCT(('Hugo.O 1'!F25:F30='Hugo.O 1'!J25:J30)*1)+SUMPRODUCT(('Hugo.O 1'!F34:F39='Hugo.O 1'!J34:J39)*1)+SUMPRODUCT(('Hugo.O 1'!F43:F48='Hugo.O 1'!J43:J48)*1)+SUMPRODUCT(('Hugo.O 1'!F52:F57='Hugo.O 1'!J52:J57)*1)+SUMPRODUCT(('Hugo.O 1'!F61:F66='Hugo.O 1'!J61:J66)*1)+SUMPRODUCT(('Hugo.O 1'!F70:F75='Hugo.O 1'!J70:J75)*1)+SUMPRODUCT(('Hugo.O 1'!F79:F84='Hugo.O 1'!J79:J84)*1)+SUMPRODUCT(('Hugo.O 1'!F88:F93='Hugo.O 1'!J88:J93)*1)+SUMPRODUCT(('Hugo.O 1'!F97:F102='Hugo.O 1'!J97:J102)*1)+SUMPRODUCT(('Hugo.O 1'!F106:F111='Hugo.O 1'!J106:J111)*1) -> 2 | D30: =SUMPRODUCT(('Hugo.O 1'!G7:G12='Hugo.O 1'!K7:K12)*1)+SUMPRODUCT(('Hugo.O 1'!G16:G21='Hugo.O 1'!K16:K21)*1)+SUMPRODUCT(('Hugo.O 1'!G25:G30='Hugo.O 1'!K25:K30)*1)+SUMPRODUCT(('Hugo.O 1'!G34:G39='Hugo.O 1'!K34:K39)*1)+SUMPRODUCT(('Hugo.O 1'!G43:G48='Hugo.O 1'!K43:K48)*1)+SUMPRODUCT(('Hugo.O 1'!G52:G57='Hugo.O 1'!K52:K57)*1)+SUMPRODUCT(('Hugo.O 1'!G61:G66='Hugo.O 1'!K61:K66)*1)+SUMPRODUCT(('Hugo.O 1'!G70:G75='Hugo.O 1'!K70:K75)*1)+SUMPRODUCT(('Hugo.O 1'!G79:G84='Hugo.O 1'!K79:K84)*1)+SUMPRODUCT(('Hugo.O 1'!G88:G93='Hugo.O 1'!K88:K93)*1)+SUMPRODUCT(('Hugo.O 1'!G97:G102='Hugo.O 1'!K97:K102)*1)+SUMPRODUCT(('Hugo.O 1'!G106:G111='Hugo.O 1'!K106:K111)*1) -> 1 | E30: =SUM('Hugo.O 1'!M:M)+Y98 -> 100 | F30: =RANK(E30,E:E,0) -> 17
B34: Points pris lors des qualifications
C35: J1 | D35: J2 | E35: J3 | F35: J4 | G35: J5 | H35: J6 | I35: J7 | J35: J8 | K35: J9 | L35: J10 | M35: J11 | N35: J12 | O35: J13 | P35: J14 | Q35: J15 | R35: J16 | S35: J17 | T35: J18 | U35: Total
B36: Dam's | C36: ='Dams 1'!M7+0 -> 25 | D36: ='Dams 1'!M8+'Dams 1'!M16 -> 0 | E36: ='Dams 1'!M17+'Dams 1'!M34 -> 25 | F36: ='Dams 1'!M25+'Dams 1'!M26+'Dams 1'!M35+'Dams 1'!M43+'Dams 1'!M52 -> 0 | G36: ='Dams 1'!M44+'Dams 1'!M53+'Dams 1'!M61+'Dams 1'!M70 -> 0 | H36: ='Dams 1'!M62+'Dams 1'!M71+'Dams 1'!M79 -> 0 | I36: ='Dams 1'!M80+'Dams 1'!M88+'Dams 1'!M89+'Dams 1'!M97+'Dams 1'!M106 -> 0 | J36: ='Dams 1'!M9+'Dams 1'!M19+'Dams 1'!M98+'Dams 1'!M107 -> 0 | K36: ='Dams 1'!M10+'Dams 1'!M18+'Dams 1'!M36 -> 0 | L36: ='Dams 1'!M27+'Dams 1'!M28+'Dams 1'!M37+'Dams 1'!M45+'Dams 1'!M54 -> 0 | M36: ='Dams 1'!M46+'Dams 1'!M55+'Dams 1'!M63+'Dams 1'!M72 -> 0 | N36: ='Dams 1'!M64+'Dams 1'!M73+'Dams 1'!M81+'Dams 1'!M90 -> 0 | O36: ='Dams 1'!M82+'Dams 1'!M91+'Dams 1'!M99+'Dams 1'!M108 -> 0 | P36: ='Dams 1'!M20+'Dams 1'!M21+'Dams 1'!M100+'Dams 1'!M109 -> 0 | Q36: ='Dams 1'!M11+'Dams 1'!M12+'Dams 1'!M29+'Dams 1'!M30+'Dams 1'!M47+'Dams 1'!M48 -> 0 | R36: ='Dams 1'!M38+'Dams 1'!M39+'Dams 1'!M56+'Dams 1'!M57+'Dams 1'!M83+'Dams 1'!M84 -> 0 | S36: ='Dams 1'!M65+'Dams 1'!M66+'Dams 1'!M74+'Dams 1'!M75+'Dams 1'!M110+'Dams 1'!M111 -> 0 | T36: ='Dams 1'!M92+'Dams 1'!M93+'Dams 1'!M101+'Dams 1'!M102 -> 0 | U36: =SUM(C36:T36) -> 50
B37: Stan | C37: ='Stan 1'!M7+0 -> 100 | D37: ='Stan 1'!M8+'Stan 1'!M16 -> 0 | E37: ='Stan 1'!M17+'Stan 1'!M34 -> 75 | F37: ='Stan 1'!M25+'Stan 1'!M26+'Stan 1'!M35+'Stan 1'!M43+'Stan 1'!M52 -> 0 | G37: ='Stan 1'!M44+'Stan 1'!M53+'Stan 1'!M61+'Stan 1'!M70 -> 0 | H37: ='Stan 1'!M62+'Stan 1'!M71+'Stan 1'!M79 -> 0 | I37: ='Stan 1'!M67+'Stan 1'!M75+'Stan 1'!M76+'Stan 1'!M84+'Stan 1'!M93 -> 0 | U37: =SUM(C37:T37) -> 175
B38: Pata | C38: ='Pata 1'!M7+0 -> 75 | D38: ='Pata 1'!M8+'Pata 1'!M16 -> 0 | E38: ='Pata 1'!M17+'Pata 1'!M34 -> 25 | F38: ='Pata 1'!M25+'Pata 1'!M26+'Pata 1'!M35+'Pata 1'!M43+'Pata 1'!M52 -> 0 | G38: ='Pata 1'!M44+'Pata 1'!M53+'Pata 1'!M61+'Pata 1'!M70 -> 0 | H38: ='Pata 1'!M62+'Pata 1'!M71+'Pata 1'!M79 -> 0 | I38: ='Pata 1'!M80+'Pata 1'!M88+'Pata 1'!M89+'Pata 1'!M97+'Pata 1'!M106 -> 0 | U38: =SUM(C38:T38) -> 100
B39: Marina | C39: ='Marina 1'!M7+0 -> 100 | D39: ='Marina 1'!M8+'Marina 1'!M16 -> 0 | E39: ='Pata 1'!M17+'Pata 1'!M34 -> 25 | F39: ='Marina 1'!M25+'Marina 1'!M26+'Marina 1'!M35+'Marina 1'!M43+'Marina 1'!M52 -> 0 | G39: ='Marina 1'!M44+'Marina 1'!M53+'Marina 1'!M61+'Marina 1'!M70 -> 0 | H39: ='Marina 1'!M62+'Marina 1'!M71+'Marina 1'!M79 -> 0 | I39: ='Marina 1'!M80+'Marina 1'!M88+'Marina 1'!M89+'Marina 1'!M97+'Marina 1'!M106 -> 0 | U39: =SUM(C39:T39) -> 125
B40: Ricco | C40: ='Ricco 1'!M7+0 -> 150 | D40: ='Ricco 1'!M8+'Ricco 1'!M16 -> 0 | E40: ='Ricco 1'!M17+'Ricco 1'!M34 -> 0 | F40: ='Ricco 1'!M25+'Ricco 1'!M26+'Ricco 1'!M35+'Ricco 1'!M43+'Ricco 1'!M52 -> 0 | G40: ='Ricco 1'!M44+'Ricco 1'!M53+'Ricco 1'!M61+'Ricco 1'!M70 -> 0 | H40: ='Ricco 1'!M62+'Ricco 1'!M71+'Ricco 1'!M79 -> 0 | I40: ='Ricco 1'!M80+'Ricco 1'!M88+'Ricco 1'!M89+'Ricco 1'!M97+'Ricco 1'!M106 -> 0 | U40: =SUM(C40:T40) -> 150
B41: Vero | C41: ='Vero 1'!M7+0 -> 25 | D41: ='Vero 1'!M8+'Vero 1'!M16 -> 135 | E41: ='Vero 1'!M17+'Vero 1'!M34 -> 25 | F41: ='Vero 1'!M25+'Vero 1'!M26+'Vero 1'!M35+'Vero 1'!M43+'Vero 1'!M52 -> 0 | G41: ='Vero 1'!M44+'Vero 1'!M53+'Vero 1'!M61+'Vero 1'!M70 -> 0 | H41: ='Vero 1'!M62+'Vero 1'!M71+'Vero 1'!M79 -> 0 | I41: ='Vero 1'!M80+'Vero 1'!M88+'Vero 1'!M89+'Vero 1'!M97+'Vero 1'!M106 -> 0 | U41: =SUM(C41:T41) -> 185
B42: Hugo C. | C42: ='Hugo 1'!M7+0 -> 0 | D42: ='Hugo 1'!M8+'Hugo 1'!M16 -> 50 | E42: ='Hugo 1'!M17+'Hugo 1'!M34 -> 25 | F42: ='Hugo 1'!M25+'Hugo 1'!M26+'Hugo 1'!M35+'Hugo 1'!M43+'Hugo 1'!M52 -> 0 | G42: ='Hugo 1'!M44+'Hugo 1'!M53+'Hugo 1'!M61+'Hugo 1'!M70 -> 0 | H42: ='Hugo 1'!M62+'Hugo 1'!M71+'Hugo 1'!M79 -> 0 | I42: ='Hugo 1'!M80+'Hugo 1'!M88+'Hugo 1'!M89+'Hugo 1'!M97+'Hugo 1'!M106 -> 0 | U42: =SUM(C42:T42) -> 75
B43: Jeje | C43: ='Jeje 1'!M7+0 -> 75 | D43: ='Jeje 1'!M8+'Jeje 1'!M16 -> 135 | E43: ='Jeje 1'!M17+'Jeje 1'!M34 -> 25 | F43: ='Jeje 1'!M25+'Jeje 1'!M26+'Jeje 1'!M35+'Jeje 1'!M43+'Jeje 1'!M52 -> 0 | G43: ='Jeje 1'!M44+'Jeje 1'!M53+'Jeje 1'!M61+'Jeje 1'!M70 -> 0 | H43: ='Jeje 1'!M62+'Jeje 1'!M71+'Jeje 1'!M79 -> 0 | I43: ='Jeje 1'!M73+'Jeje 1'!M81+'Jeje 1'!M82+'Jeje 1'!M90+'Jeje 1'!M99 -> 0 | U43: =SUM(C43:T43) -> 235
B44: Laura | C44: ='Laura 1'!M7+0 -> 100 | D44: ='Laura 1'!M8+'Laura 1'!M16 -> 0 | E44: ='Laura 1'!M17+'Laura 1'!M34 -> 25 | F44: ='Laura 1'!M25+'Laura 1'!M26+'Laura 1'!M35+'Laura 1'!M43+'Laura 1'!M52 -> 0 | G44: ='Laura 1'!M44+'Laura 1'!M53+'Laura 1'!M61+'Laura 1'!M70 -> 0 | H44: ='Laura 1'!M62+'Laura 1'!M71+'Laura 1'!M79 -> 0 | I44: ='Laura 1'!M74+'Laura 1'!M82+'Laura 1'!M83+'Laura 1'!M91+'Laura 1'!M100 -> 0 | U44: =SUM(C44:T44) -> 125
...

Sheet Planning
B3: Phase de qualification
B4: Journées | C4: Dates | D4: M1 | E4: M2 | F4: M3 | G4: M4 | H4: M5 | I4: M6
B5: J1 | C5: 46184 | D5: Mex - AdS
B6: J2 | C6: 46185 | D6: Can - Bos | E6: Cor - Tch
B7: J3 | C7: 46186 | D7: Qat - Sui | E7: USA - Para
B8: J4 | C8: 46187 | D8: All - Cura | E8: P-B - Jap | F8: Aus - Turk | G8: Bre - Maroc | H8: Haï - Eco
B9: J5 | C9: 46188 | D9: Esp - Cap | E9: Bel - Egy | F9: CdI - Equ | G9: Sué - Tun
B10: J6 | C10: 46189 | D10: Fra - Sen | E10: Arab - Uru | F10: Iran - N-Z
B11: J7 | C11: 46190 | D11: Por - RDC | E11: Ang - Cro | F11: Irak - Nor | G11: Arg - Alg | H11: Aut - Jor
B12: J8 | C12: 46191 | D12: AdS - Tch | E12: Sui - Bos | F12: Gha - Pana | G12: Ouz - Col
B13: J9 | C13: 46192 | D13: USA - Aus | E13: Qat - Can | F13: Mex - Cor
B14: J10 | C14: 46193 | D14: P-B - Sué | E14: Eco - Maroc | F14: Bré - Haï | G14: Turk - Para | H14: All - CdI
B15: J11 | C15: 46194 | D15: Esp - Arab | E15: Bel - Iran | F15: Equ - Cura | G15: Tun - Jap
B16: J12 | C16: 46195 | D16: Arg - Aut | E16: Fra - Irak | F16: Uru - Cap | G16: N-Z - Egy
B17: J13 | C17: 46196 | D17: Por - Ouz | E17: Ang - Gha | F17: Nor - Sen | G17: Jor - Alg
B18: J14 | C18: 46197 | D18: Sui - Can | E18: Bos - Qat | F18: Pana - Cro | G18: Col - RDC
B19: J15 | C19: 46198 | D19: Equ - All | E19: Cura - CdI | F19: Eco - Bré | G19: Maroc - Haï | H19: Tch - Mex | I19: AsD - Cor
B20: J16 | C20: 46199 | D20: Nor - Fra | E20: Sen - Irak | F20: Tun - P-B | G20: Jap - Sué | H20: Turk - USA | I20: Para - Aus
B21: J17 | C21: 46200 | D21: Pana - Ang | E21: Cro - Gha | F21: Uru - Esp | G21: Cap - Arab | H21: N-Z - Bel | I21: Egy - Iran
B22: J18 | C22: 46201 | D22: Col - Por | E22: RdC - Ouz | F22: Jor - Arg | G22: Alg - Aut
B24: Phase finale
B25: J18 | C25: 46201 | D25: (Match 73) 2A - 2B
B26: J19 | C26: 46202 | D26: (Match 74) 1E - M3(ABCDF) | F26: (Match 76) 1C - 2F
B27: J20 | C27: 46203 | D27: (Match 75) 1F - 2C | F27: (Match 77) 1I - M3(CDFGH) | H27: (Match 78) 2E - 2I
B28: J21 | C28: 46204 | D28: (Match 79) 1A - M3(CEFHI) | F28: (Match 80) 1L - M3(EHIJK) | H28: (Match 82) 1G - M3(AEHIJ)
B29: J22 | C29: 46205 | D29: (Match 81) 1D - M3(BEFIJ) | F29: (Match 84) 1H - 2J
B30: J23 | C30: 46206 | D30: (Match 83) 2K - 2L | F30: (Match 85) 1B - M3(EFGIJ) | H30: (Match 88) 2D - 2G
B31: J24 | C31: 46207 | D31: (Match 86) 1J - 2H | F31: (Match 87) 1K - M3(DEIJL)
B33: Huitièmes de finale
B34: J24 | C34: 46207 | D34: (Match 89) Winner match 77 - Winner match 74 | G34: (Match 90) Winner match 73 - Winner match 75
B35: J25 | C35: 46208 | D35: (Match 91) Winner match 76 - Winner match 78
B36: J26 | C36: 46209 | D36: (Match 92) Winner match 79 - Winner match 80 | G36: (Match 93) Winner match 83 - Winner match 84
B37: J27 | C37: 46210 | D37: (Match 94) Winner match 81 - Winner match 82 | G37: (Match 95) Winner match 86 - Winner match 88 | J37: (Match 96) Winner match 85 - Winner match 87
B38: J28 | C38: 46211 | D38: Repos
B40: Quarts de finale
B41: J29 | C41: 46212 | D41: (Match 97) Winner match 89 - Winner match 90
B42: J30 | C42: 46213 | D42: (Match 98) Winner match 93 - Winner match 94
B43: J31 | C43: 46214 | D43: (Match 99) Winner match 91 - Winner match 92
B44: J32 | C44: 46215 | D44: (Match 100) Winner match 95 - Winner match 96
B45: J33 | C45: 46216 | D45: Repos
...

Sheet Boosters
B2: Numéros | C2: Journées | D2: Dates | E2: Matchs | F2: Détails
B3: B1 | C3: 1 | D3: 46184 | E3: Mex - AdS | F3: Giminez but de la tete
B4: B2 | F4: Nul mi-temps
B5: B3 | C5: 2 | D5: 46185 | E5: Cor - Tch | F5: -2,5 carton jaune
B6: B4 | F6: shick et sulc 2 but ou +
B7: B5 | E7: Can - Bos | F7: Buchanan decisif
B8: B6 | F8: Alajbegovic plus decisif que david
B9: B7 | C9: 3 | D9: 46186 | E9: USA - Para | F9: But d'un defenseur
B10: B8 | F10: Balogun + Pulisic decisif + 2 fois
B11: B9 | E11: Qat - Sui | F11: Nul mi-temps
B12: B10 | F12: Xhaka decisif
B13: B11 | C13: 4 | D13: 46187 | E13: Bre - Maroc | F13: Casemiro decisif
B14: B12 | F14: + 1,5 a la mi-temps
B15: B13 | E15: Haï - Eco | F15: Isidor buteur
B16: B14 | F16: + 3,5 jaune
B17: B15 | E17: Aus - Turk | F17: uzun decisif 2 fois ou +
B18: B16 | F18: 20 fautes ou +
B19: B17 | E19: All - Cura | F19: But d'un defenseur
B20: B18 | F20: Nul mi-temps
B21: B19 | E21: P-B - Jap | F21: Reijnders ou tanaka buteur
B22: B20 | F22: - 3,5 jaunes
B23: B21 | C23: 5 | D23: 46188 | E23: CdI - Equ | F23: Diallo ou Pepe buteur
B24: B22 | F24: But sur Peno
B25: B23 | E25: Sué - Tun | F25: Isak pas decisif
B26: B24 | F26: Tunisie cleen sheet
B27: B25 | E27: Esp - Cap | F27: But sur Peno
B28: B26 | F28: +2,5 but a la mi-temps
B29: B27 | E29: Bel - Egy | F29: Doku plus decisif que KDB
B30: B28 | F30: Salah Buteur
B31: B29 | C31: 6 | D31: 46189 | E31: Arab - Uru | F31: Valeverde decif +2 fois
B32: B30 | F32: 1 carton rouge ou +
B33: B31 | E33: Iran - N-Z | F33: Wood + Taremi 2 but ou +
B34: B32 | F34: But sur Peno
B35: B33 | E35: Fra - Sen | F35: Mané buteur
B36: B34 | F36: But d'un defenseur
B37: B35 | C37: 7 | D37: 46190 | E37: Irak - Nor | F37: Nusa decisif
B38: B36 | F38: Haaland but de la tete
B39: B37 | E39: Arg - Alg | F39: Algerie marque en premier
B40: B38 | F40: But sur Coup franc
B41: B39 | E41: Aut - Jor | F41: But d'un defenseur
...

Sheet Dams 1
B1: Joueur : Dam's | C1: Meilleur buteur de la CDM : | F1: Mbappé
C2: Meilleur passeur de la CDM : | F2: Viti-goat
C3: Meilleur joueur de la CDM : | F3: Olise
C4: Gagnant de la CDM : | F4: Portugal
A6: Poule A | D6: Dates | E6: Rencontres | F6: Mes prono | G6: Mes scores | H6: Mes Booster | I6: Côte du prono | J6: Vainqueurs | K6: Les résultats | L6: Booster validé | M6: Points gagnés
A7: Equipe A | B7: Mexique | D7: 46184 | E7: A vs C | F7: A | G7: 2 - 1 | H7: B2 | I7: 1 - 3 | J7: A | K7: 2 - 0 | L7: non | M7: =IF(J7=F7,IF( OR(I7="3 - 1",I7="4 - 1",I7="4 - 2"),100,IF( OR(I7="2 - 1",I7="3 - 2",I7="4 - 3"),75,IF(I7="nul",60,IF( OR(I7="3 - 4",I7="2 - 3",I7="1 - 2"),50,IF( OR(I7="1 - 3",I7="2 - 4",I7="1 - 4"),25,0)))))+IF(K7=G7,+75,0)+IF(L7="oui",+50,0))+0 -> 25
A8: Equipe B | B8: Coree du sud | D8: 46185 | E8: B vs D | F8: N | G8: 1 - 1 | H8: B3 | I8: nul | J8: B | K8: 2 - 1 | L8: oui | M8: =IF(J8=F8,IF( OR(I8="3 - 1",I8="4 - 1",I8="4 - 2"),100,IF( OR(I8="2 - 1",I8="3 - 2",I8="4 - 3"),75,IF(I8="nul",60,IF( OR(I8="3 - 4",I8="2 - 3",I8="1 - 2"),50,IF( OR(I8="1 - 3",I8="2 - 4",I8="1 - 4"),25,0)))))+IF(K8=G8,+75,0)+IF(L8="oui",+50,0))+0 -> 0
A9: Equipe C | B9: Afrique du sud | D9: 46191 | E9: C vs D | F9: ... | K9: ... | M9: =IF(J9=F9,IF( OR(I9="3 - 1",I9="4 - 1",I9="4 - 2"),100,IF( OR(I9="2 - 1",I9="3 - 2",I9="4 - 3"),75,IF(I9="nul",60,IF( OR(I9="3 - 4",I9="2 - 3",I9="1 - 2"),50,IF( OR(I9="1 - 3",I9="2 - 4",I9="1 - 4"),25,0)))))+IF(K9=G9,+75,0)+IF(L9="oui",+50,0))+0 -> 0
A10: Equipe D | B10: Republique tchèque | D10: 46192 | E10: A vs B | F10: ... | K10: ... | M10: =IF(J10=F10,IF( OR(I10="3 - 1",I10="4 - 1",I10="4 - 2"),100,IF( OR(I10="2 - 1",I10="3 - 2",I10="4 - 3"),75,IF(I10="nul",60,IF( OR(I10="3 - 4",I10="2 - 3",I10="1 - 2"),50,IF( OR(I10="1 - 3",I10="2 - 4",I10="1 - 4"),25,0)))))+IF(K10=G10,+75,0)+IF(L10="oui",+50,0))+0 -> 0
D11: 46198 | E11: A vs D | F11: ... | K11: ... | M11: =IF(J11=F11,IF( OR(I11="3 - 1",I11="4 - 1",I11="4 - 2"),100,IF( OR(I11="2 - 1",I11="3 - 2",I11="4 - 3"),75,IF(I11="nul",60,IF( OR(I11="3 - 4",I11="2 - 3",I11="1 - 2"),50,IF( OR(I11="1 - 3",I11="2 - 4",I11="1 - 4"),25,0)))))+IF(K11=G11,+75,0)+IF(L11="oui",+50,0))+0 -> 0
D12: 46198 | E12: B vs C | F12: ... | K12: ... | M12: =IF(J12=F12,IF( OR(I12="3 - 1",I12="4 - 1",I12="4 - 2"),100,IF( OR(I12="2 - 1",I12="3 - 2",I12="4 - 3"),75,IF(I12="nul",60,IF( OR(I12="3 - 4",I12="2 - 3",I12="1 - 2"),50,IF( OR(I12="1 - 3",I12="2 - 4",I12="1 - 4"),25,0)))))+IF(K12=G12,+75,0)+IF(L12="oui",+50,0))+0 -> 0
A15: Poule B | D15: Dates | E15: Rencontres | F15: Mes prono | G15: Mes scores | H15: Mes Booster | I15: Côte du prono | J15: Vainqueurs | K15: Les résultats | L15: Booster validé | M15: Points gagnés
A16: Equipe A | B16: Canada | D16: 46185 | E16: A vs D | F16: A | G16: 2 - 1 | I16: 2 - 4 | J16: nul | K16: 1 - 1 | M16: =IF(J16=F16,IF( OR(I16="3 - 1",I16="4 - 1",I16="4 - 2"),100,IF( OR(I16="2 - 1",I16="3 - 2",I16="4 - 3"),75,IF(I16="nul",60,IF( OR(I16="3 - 4",I16="2 - 3",I16="1 - 2"),50,IF( OR(I16="1 - 3",I16="2 - 4",I16="1 - 4"),25,0)))))+IF(K16=G16,+75,0)+IF(L16="oui",+50,0))+0 -> 0
